Workbook

Sheet 📝_نموذج_الإدخال
A1: 📝 نموذج تسجيل حالة حمل عالي الخطورة - تجمع جازان الصحي 2026
A2: ✅ اضغط على الخلية الصفراء للإدخال - القوائم المنسدلة جاهزة للاختيار
F3: 🔍 البحث عن حالة موجودة
A4: 📋 البيانات الأساسية للمريضة | F4: أدخل السجل المدني: | G4: 1115947606
A5: اسم المريضة: | C5: رقم الهوية: | F5: الاسم: | G5: {=IFERROR(INDEX(البيانات!$U$2:$U$300,MATCH($G$4*1,البيانات!$V$2:$V$300*1,0)),IFERROR(INDEX(البيانات!$U$2:$U$300,MATCH(TEXT($G$4,"0"),البيانات!$V$2:$V$300,0)),"غير موجود"))} -> جنان حسين محمد حكمي
A6: تاريخ الميلاد: | C6: العمر: | F6: العمر: | G6: {=IFERROR(INDEX(البيانات!$T$2:$T$300,MATCH($G$4*1,البيانات!$V$2:$V$300*1,0)),IFERROR(INDEX(البيانات!$T$2:$T$300,MATCH(TEXT($G$4,"0"),البيانات!$V$2:$V$300,0)),"—"))} -> 24
A7: رقم الجوال: | C7: العنوان: | F7: القطاع: | G7: {=IFERROR(INDEX(البيانات!$F$2:$F$300,MATCH($G$4*1,البيانات!$V$2:$V$300*1,0)),IFERROR(INDEX(البيانات!$F$2:$F$300,MATCH(TEXT($G$4,"0"),البيانات!$V$2:$V$300,0)),"—"))} -> القطاع المركزي
A8: القطاع: | C8: المركز الصحي: | F8: رقم الجوال: | G8: {=IFERROR(INDEX(البيانات!$Y$2:$Y$300,MATCH($G$4*1,البيانات!$V$2:$V$300*1,0)),IFERROR(INDEX(البيانات!$Y$2:$Y$300,MATCH(TEXT($G$4,"0"),البيانات!$V$2:$V$300,0)),"—"))} -> 556898292
A9: تاريخ LMP: | C9: عمر الحمل: | F9: المستشفى: | G9: {=IFERROR(INDEX(البيانات!$AM$2:$AM$300,MATCH($G$4*1,البيانات!$V$2:$V$300*1,0)),IFERROR(INDEX(البيانات!$AM$2:$AM$300,MATCH(TEXT($G$4,"0"),البيانات!$V$2:$V$300,0)),"—"))} -> مستشفي جازان العام
A10: تاريخ الزيارة: | C10: اسم الطبيب: | F10: VTE: | G10: {=IFERROR(INDEX(البيانات!$AD$2:$AD$300,MATCH($G$4*1,البيانات!$V$2:$V$300*1,0)),IFERROR(INDEX(البيانات!$AD$2:$AD$300,MATCH(TEXT($G$4,"0"),البيانات!$V$2:$V$300,0)),"—"))} -> No
F11: Enoxaparin: | G11: {=IFERROR(INDEX(البيانات!$AE$2:$AE$300,MATCH($G$4*1,البيانات!$V$2:$V$300*1,0)),IFERROR(INDEX(البيانات!$AE$2:$AE$300,MATCH(TEXT($G$4,"0"),البيانات!$V$2:$V$300,0)),"—"))} -> 0
A12: ⚠️ عوامل الخطورة والتقييم | F12: تاريخ الزيارة: | G12: {=IFERROR(INDEX(البيانات!$P$2:$P$300,MATCH($G$4*1,البيانات!$V$2:$V$300*1,0)),IFERROR(INDEX(البيانات!$P$2:$P$300,MATCH(TEXT($G$4,"0"),البيانات!$V$2:$V$300,0)),"—"))} -> 46077
A13: VTE عالي الخطورة؟ | C13: تم وصف Enoxaparin؟ | F13: تاريخ الموعد: | G13: {=IFERROR(INDEX(البيانات!$AI$2:$AI$300,MATCH($G$4*1,البيانات!$V$2:$V$300*1,0)),IFERROR(INDEX(البيانات!$AI$2:$AI$300,MATCH(TEXT($G$4,"0"),البيانات!$V$2:$V$300,0)),"—"))} -> 5/3/2026
A14: مستوى الخطورة: | C14: توصية الإحالة: | F14: الالتزام: | G14: {=IFERROR(INDEX(البيانات!$AK$2:$AK$300,MATCH($G$4*1,البيانات!$V$2:$V$300*1,0)),IFERROR(INDEX(البيانات!$AK$2:$AK$300,MATCH(TEXT($G$4,"0"),البيانات!$V$2:$V$300,0)),"—"))} -> ❌ غير ملتزم
A15: المستشفى المحال إليه: | C15: تاريخ الموعد: | F15: الحضور: | G15: {=IFERROR(INDEX(البيانات!$AJ$2:$AJ$300,MATCH($G$4*1,البيانات!$V$2:$V$300*1,0)),IFERROR(INDEX(البيانات!$AJ$2:$AJ$300,MATCH(TEXT($G$4,"0"),البيانات!$V$2:$V$300,0)),"—"))} -> تم الحظور
A17: 📞 بيانات المتابعة | F17: 💡 أدخل رقم السجل المدني للبحث
A18: إفادة الحضور: | C18: تصنيف المنسق:
A19: ملاحظات:
A21: 📖 دليل سريع للاستخدام
A22: 1️⃣ | B22: أدخل بيانات المريضة الأساسية في الحقول الصفراء
A23: 2️⃣ | B23: اختر القطاع والمستشفى من القوائم المنسدلة
A24: 3️⃣ | B24: حدد مستوى الخطورة وتوصية الإحالة
A25: 4️⃣ | B25: بعد الإدخال، انسخ البيانات إلى ورقة 'البيانات'
A26: 5️⃣ | B26: جميع المؤشرات ستتحدث تلقائياً!
A28: 🏥 ربط القطاعات بالمستشفيات | C28: 🎯 تصنيفات المنسق
A29: القطاع | B29: المستشفى المحال إليه | C29: التصنيف | D29: الإجراء
A30: المركزي + فرسان | B30: مستشفى جازان العام | C30: 🟢 منخفض | D30: تعود للمركز الصحي
A31: الغربي + الجبلي | B31: مستشفى صبيا العام | C31: 🟡 عالي | D31: متابعة بنفس المستشفى
A32: الأوسط + بني مالك | B32: مستشفى أبو عريش العام | C32: 🔴 عالي جداً | D32: تحويل لـ KFCH
A33: الجنوبي | B33: مستشفى صامطة العام
A34: الشمالي | B34: مستشفى بيش العام
A35: الحالات الحرجة | B35: مستشفى الملك فهد (KFCH)
A37: ⚠️ ملاحظة هامة: مؤشر الالتزام يُحسب تلقائياً - يجب حجز الموعد خلال يومين عمل (الجمعة والسبت مستثناة)

Sheet 📖_دليل_العمل
A1: 📖 دليل العمل الشامل - نظام إدارة الحمل عالي الخطورة - تجمع جازان الصحي 2026
A3: 📑 فهرس المحتويات
A4: الرقم | B4: القسم | C4: الوصف
A5: 1️⃣ | B5: نظرة عامة | C5: وصف شامل للنظام وأهدافه
A6: 2️⃣ | B6: هيكل الملف | C6: شرح 18 ورقة عمل
A7: 3️⃣ | B7: إدخال حالة جديدة | C7: خطوات التسجيل والإدخال
A8: 4️⃣ | B8: توزيع القطاعات | C8: ربط القطاعات بالمستشفيات
A9: 5️⃣ | B9: تصنيفات المنسق | C9: خيارات التصنيف الثلاثة
A10: 6️⃣ | B10: مؤشرات الأداء | C10: شرح KPIs والحسابات
A11: 7️⃣ | B11: صيغة الالتزام | C11: حساب مؤشر الالتزام
A12: 8️⃣ | B12: نموذج الإدخال | C12: استخدام نموذج الإدخال والتحديث
A13: 9️⃣ | B13: التقارير | C13: إنشاء وتصدير التقارير
A14: 🔟 | B14: إرشادات هامة | C14: نصائح وتحذيرات
A16: 1️⃣ نظرة عامة على النظام
A17: الهدف: | B17: إدارة ومتابعة حالات الحمل عالي الخطورة في تجمع جازان الصحي
A18: النطاق: | B18: 8 قطاعات + 6 مستشفيات (5 عامة + الملك فهد المركزي)
A19: المستخدمون: | B19: منسقو الإحالات في المراكز الصحية والمستشفيات
A20: التحديث: | B20: تلقائي - جميع المؤشرات والتقارير تتحدث فوراً عند إضافة البيانات
A21: مصدر البيانات: | B21: Microsoft Forms - متصل بورقة البيانات
A23: 2️⃣ هيكل الملف (18 ورقة)
A24: الورقة | B24: الوظيفة | C24: النوع | D24: الوصف
A25: 📖_دليل_العمل | B25: دليل الاستخدام الشامل | C25: مرجع 📚 | D25: هذه الورقة
A26: 📝_نموذج_الإدخال | B26: نموذج تسجيل حالة جديدة | C26: إدخال ✏️ | D26: قوائم منسدلة
A27: 📊_لوحة_التحكم | B27: المؤشرات الرئيسية + البحث | C27: عرض 👁️ | D27: لوحة تحكم مركزية
A28: 📈_التقارير | B28: KPIs شهرية + رسوم بيانية | C28: عرض + فلتر 📊 | D28: تقارير شهرية وسنوية
A29: توزيع_الإحالات | B29: توزيع على المستشفيات | C29: عرض 👁️ | D29: إحصائيات التوزيع
A30: النظام_الذكي | B30: نظام توقع الإحالات | C30: عرض 👁️ | D30: نقاط الخطورة
A31: إحالات_KFCH | B31: إحالات الملك فهد | C31: إدخال ✏️ | D31: تلقائي من البيانات
A32: إحالات_جازان | B32: إحالات مستشفى جازان | C32: إدخال ✏️ | D32: المركزي + فرسان
A33: إحالات_صبيا | B33: إحالات مستشفى صبيا | C33: إدخال ✏️ | D33: الغربي + الجبلي
A34: إحالات_أبو_عريش | B34: إحالات أبو عريش | C34: إدخال ✏️ | D34: الأوسط + بني مالك
A35: إحالات_صامطة | B35: إحالات صامطة | C35: إدخال ✏️ | D35: الجنوبي
... A40: البيانات | B40: البيانات من Forms | C40: مصدر 📁 | D40: لا تعدل
A42: 3️⃣ خطوات إدخال حالة جديدة
A43: الخطوة | B43: الإجراء | C43: التفاصيل
A44: 1 | B44: افتح ورقة 'البيانات' | C44: أو استخدم نموذج الإدخال 📝
A45: 2 | B45: أضف بيانات المريضة | C45: البيانات تأتي من Forms تلقائياً
A46: 3 | B46: أدخل اسم المستشفى في عمود AR | C46: جازان/صبيا/أبو عريش/صامطة/بيش/الملك فهد
A47: 4 | B47: أدخل تاريخ الموعد في عمود AS | C47: تاريخ موعد المريضة
A48: 5 | B48: أدخل إفادة الحضور في عمود AJ | C48: حضرت / لم تحضر / بانتظار
...

Sheet توزيع_الإحالات
A1: 📊 لوحة توزيع الإحالات على المستشفيات - تجمع جازان الصحي 2026
A3: 📈 ملخص الإحالات | D3: 🏥 توزيع الإحالات حسب المستشفى
A4: إجمالي الحالات المسجلة | B4: =COUNTA(البيانات!V2:V1000) -> 264 | D4: المستشفى | E4: عدد الإحالات | F4: النسبة
A5: الحالات تحتاج إحالة | B5: =COUNTIFS(النظام_الذكي!G:G,">=4") -> 113 | D5: مستشفى الملك فهد المركزي (تحويلات) | E5: {=SUMPRODUCT((ISNUMBER(SEARCH("فهد",البيانات!$AS$2:$AS$300)))*1)} -> 1 | F5: =IF(E5=0,"0%",TEXT(E5/SUM(E5:E10),"0%")) -> 0%
A6: متابعة في المركز | B6: =B4-B5 -> 151 | D6: مستشفى صبيا العام | E6: =COUNTIF(البيانات!$AS:$AS,"*صبيا*") -> 38 | F6: =IF(E6=0,"0%",TEXT(E6/SUM($E$5:$E$10),"0%")) -> 15%
D7: مستشفى أبو عريش العام | E7: =COUNTIF(البيانات!$AS:$AS,"*عريش*") -> 31 | F7: =IF(E7=0,"0%",TEXT(E7/SUM($E$5:$E$10),"0%")) -> 12%
A8: 🔴 حالات حرجة | B8: =COUNTIFS(النظام_الذكي!H:H,"*حرج*") -> 36 | D8: مستشفى جازان العام | E8: =COUNTIF(البيانات!$AS:$AS,"*جازان*") -> 148 | F8: =IF(E8=0,"0%",TEXT(E8/SUM($E$5:$E$10),"0%")) -> 56%
A9: 🟠 حالات عالية | B9: =COUNTIFS(النظام_الذكي!H:H,"*عالي*")-B8 -> 21 | D9: مستشفى صامطة العام | E9: =COUNTIF(البيانات!$AS:$AS,"*صامط*") -> 29 | F9: =IF(E9=0,"0%",TEXT(E9/SUM($E$5:$E$10),"0%")) -> 11%
A10: 🟡 حالات متوسطة | B10: =COUNTIFS(النظام_الذكي!H:H,"*متوسط*") -> 63 | D10: مستشفى بيش العام | E10: =COUNTIF(البيانات!$AS:$AS,"*بيش*") -> 15 | F10: =IF(E10=0,"0%",TEXT(E10/SUM($E$5:$E$10),"0%")) -> 6%
A13: 📍 توزيع الحالات حسب القطاع | E13: 💡 تعليمات الاستخدام
A14: القطاع | B14: عدد الحالات | C14: المستشفى المحال إليه | E14: 1️⃣ | F14: كل مستشفى له ورقة خاصة بإحالاته
A15: القطاع المركزي | B15: =COUNTIFS(البيانات!F:F,"*مركزي*")+COUNTIFS(البيانات!F:F,"*Central*") -> 226 | C15: مستشفى جازان العام | E15: 2️⃣ | F15: الحالات تُصنف تلقائياً حسب القطاع
A16: القطاع الأوسط | B16: =COUNTIFS(البيانات!F:F,"*أوسط*")+COUNTIFS(البيانات!F:F,"*Middle*") -> 22 | C16: مستشفى أبو عريش العام | E16: 3️⃣ | F16: الحالات الحرجة تُحال لمستشفى الملك فهد
A17: القطاع الغربي | B17: =COUNTIFS(البيانات!F:F,"*غربي*")+COUNTIFS(البيانات!F:F,"*Western*") -> 43 | C17: مستشفى صبيا العام | E17: 4️⃣ | F17: البيانات تتحدث تلقائياً من ورقة البيانات
A18: القطاع الجنوبي | B18: =COUNTIFS(البيانات!F:F,"*جنوبي*")+COUNTIFS(البيانات!F:F,"*Southern*") -> 58 | C18: مستشفى صامطة العام | E18: 5️⃣ | F18: للتحديث: أضف البيانات الجديدة في ورقة البيانات
A19: القطاع الشمالي | B19: =COUNTIFS(البيانات!F:F,"*شمالي*")+COUNTIFS(البيانات!F:F,"*Northern*") -> 30 | C19: مستشفى بيش العام
A20: القطاع الجبلي | B20: =COUNTIFS(البيانات!F:F,"*جبلي*")+COUNTIFS(البيانات!F:F,"*aljabaly*") -> 20 | C20: مستشفى صبيا العام
A21: قطاع بني مالك | B21: =COUNTIFS(البيانات!F:F,"*بني مالك*")+COUNTIFS(البيانات!F:F,"*Bani Malik*") -> 5 | C21: مستشفى أبو عريش العام
A22: قطاع فرسان | B22: =COUNTIFS(البيانات!F:F,"*فرسان*")+COUNTIFS(البيانات!F:F,"*Farasan*") -> 0 | C22: مستشفى جازان العام
A24: 📐 صيغة حساب الالتزام:
A25: 🔹 الصيغة: IF(NETWORKDAYS.INTL(تاريخ_الزيارة,تاريخ_الموعد,"0000011")-1<=2,"✅ ملتزم","❌ غير ملتزم")
A26: 🔹 "0000011" = استثناء الجمعة (اليوم 6) والسبت (اليوم 7)
A27: 🔹 إذا كان الفرق ≤ 2 أيام عمل = ✅ ملتزم، وإلا = ❌ غير ملتزم
A29: 📊 مؤشر الالتزام (حجز الموعد خلال يومين عمل)
A30: المؤشر | B30: العدد | C30: النسبة
A31: ✅ ملتزم (خلال يومين عمل) | B31: =COUNTIF(البيانات!AK2:AK265,"✅ ملتزم") -> 117 | C31: =TEXT(B31/(B31+B32),"0%") -> 47%
A32: ❌ غير ملتزم (أكثر من يومين) | B32: =COUNTIF(البيانات!AK2:AK265,"❌ غير ملتزم") -> 132 | C32: =TEXT(B32/(B31+B32),"0%") -> 53%
A33: ⏳ بانتظار الموعد | B33: =COUNTIF(البيانات!AK2:AK265,"⏳ بانتظار") -> 15 | C33: =TEXT(B33/(B31+B32+B33),"0%") -> 6%
A35: 💡 ملاحظة: الالتزام = حجز الموعد خلال يومين عمل (الجمعة والسبت مستثناة)

Sheet 📊_لوحة_التحكم
A1: 🏥 لوحة التحكم المركزية - مشروع تحسين مسار الحمل عالي الخطورة - تجمع جازان الصحي 2026
A2: 📅 آخر تحديث: | B2: 46154
A4: 📊 إجمالي الحالات | C4: 🔴 VTE عالي | E4: ⚠️ بدون علاج | G4: ✅ تم العلاج | I4: 👵 عمر > 40 | K4: 🚨 حرجة
A5: =COUNTA(البيانات!V2:V1000) -> 264 | C5: =COUNTIF(البيانات!AD2:AD1000,"Yes") -> 45 | E5: =COUNTIFS(البيانات!AD2:AD1000,"Yes",البيانات!AE2:AE1000,"No") -> 27 | G5: =COUNTIFS(البيانات!AD2:AD1000,"Yes",البيانات!AE2:AE1000,"Yes") -> 18 | I5: =COUNTIF(البيانات!T2:T1000,">40") -> 21 | K5: =COUNTIF(النظام_الذكي!H8:H500,"🔴 حرج") -> 36
A7: 🏥 توزيع الإحالات على المستشفيات | F7: 📊 توزيع مستويات الخطورة
A8: المستشفى | B8: عدد الإحالات | C8: النسبة | D8: الحالات الحرجة | F8: المستوى | G8: العدد | H8: النسبة | I8: الإجراء
A9: مستشفى جازان العام | B9: =COUNTIF(البيانات!$AS:$AS,"*جازان*") -> 148 | C9: =IF(B9=0,"0%",TEXT(B9/SUM($B$9:$B$14),"0%")) -> 56% | D9: 3 | F9: 🔴 حرج | G9: =COUNTIFS(النظام_الذكي!H:H,"*حرج*") -> 36 | H9: 0.07 | I9: إحالة فورية للمستشفى
A10: مستشفى صبيا العام | B10: =COUNTIF(البيانات!$AS:$AS,"*صبيا*") -> 38 | C10: =IF(B10=0,"0%",TEXT(B10/SUM($B$9:$B$14),"0%")) -> 15% | D10: 2 | F10: 🟠 عالي | G10: =COUNTIFS(النظام_الذكي!H:H,"*عالي*")-G9 -> 21 | H10: 0.11 | I10: إحالة تخصصية
A11: مستشفى أبو عريش العام | B11: =COUNTIF(البيانات!$AS:$AS,"*عريش*") -> 31 | C11: =IF(B11=0,"0%",TEXT(B11/SUM($B$9:$B$14),"0%")) -> 12% | D11: 2 | F11: 🟡 متوسط | G11: =COUNTIFS(النظام_الذكي!H:H,"*متوسط*") -> 63 | H11: 0.22 | I11: متابعة مكثفة
A12: مستشفى صامطة العام | B12: =COUNTIF(البيانات!$AS:$AS,"*صامط*") -> 29 | C12: =IF(B12=0,"0%",TEXT(B12/SUM($B$9:$B$14),"0%")) -> 11% | D12: 3 | F12: 🟢 منخفض | G12: =COUNTIFS(النظام_الذكي!H:H,"*منخفض*") -> 108 | H12: 0.6 | I12: متابعة روتينية
A13: مستشفى بيش العام | B13: =COUNTIF(البيانات!$AS:$AS,"*بيش*") -> 15 | C13: =IF(B13=0,"0%",TEXT(B13/SUM($B$9:$B$14),"0%")) -> 6% | D13: 1
A14: مستشفى الملك فهد (KFCH) | B14: {=SUMPRODUCT((ISNUMBER(SEARCH("فهد",البيانات!$AS$2:$AS$300)))*1)} -> 1 | C14: =IF(B14=0,"0%",TEXT(B14/SUM(B9:B14),"0%")) -> 0% | D14: 0
A16: 🔍 البحث بالسجل المدني | F16: ⏱️ مؤشر الالتزام (حجز الموعد خلال يومين عمل)
A17: أدخل السجل المدني: | F17: المؤشر | G17: العدد | H17: النسبة | I17: الحالة
A18: الاسم: | B18: =IFERROR(_xlfn.XLOOKUP(B17,البيانات!V:V,البيانات!U:U,"غير موجود"),"غير موجود") -> 0 | F18: ✅ ملتزم (≤ يومين عمل) | G18: =COUNTIF(البيانات!AK2:AK265,"✅ ملتزم") -> 117 | H18: =TEXT(G18/(G18+G19),"0%") -> 47% | I18: 🟢 جيد
A19: العمر: | B19: =IFERROR(_xlfn.XLOOKUP(B17,البيانات!V:V,البيانات!T:T,"-"),"-") -> 0 | F19: ❌ غير ملتزم (> يومين) | G19: =COUNTIF(البيانات!AK2:AK265,"❌ غير ملتزم") -> 132 | H19: =TEXT(G19/(G18+G19),"0%") -> 53% | I19: 🔴 يحتاج متابعة
A20: القطاع: | B20: =IFERROR(_xlfn.XLOOKUP(B17,البيانات!V:V,البيانات!F:F,"-"),"-") -> 0 | F20: ⏳ بانتظار الموعد | G20: =COUNTIF(البيانات!AK2:AK265,"⏳ بانتظار") -> 15 | H20: =TEXT(G20/(G18+G19+G20),"0%") -> 6% | I20: ⚪ معلق
A21: رقم الجوال: | B21: =IFERROR(_xlfn.XLOOKUP(B17,البيانات!V:V,البيانات!Y:Y,"-"),"-") -> 0
A22: VTE: | B22: =IFERROR(_xlfn.XLOOKUP(B17,البيانات!V:V,البيانات!AD:AD,"-"),"-") -> 0 | F22: 💡 ملاحظة: الالتزام يُحسب بعد إدخال تاريخ الموعد
A23: العلاج: | B23: =IFERROR(_xlfn.XLOOKUP(B17,البيانات!V:V,البيانات!AE:AE,"-"),"-") -> 0
A25: 🚨 تنبيهات عاجلة
A26: ⚠️ حالات VTE بدون Enoxaparin: | B26: =COUNTIFS(البيانات!AD:AD,"Yes",البيانات!AE:AE,"No") -> 27 | C26: حالة تحتاج متابعة فورية | F26: 1️⃣ | G26: للبحث عن مريضة: أدخل السجل المدني في الخانة الصفراء
A27: 🔴 حالات حرجة تحتاج إحالة: | B27: =COUNTIFS(النظام_الذكي!H:H,"*حرج*") -> 36 | C27: حالة حرجة | F27: 2️⃣ | G27: لمتابعة حالة: اذهب لورقة المستشفى المعني
A28: 👵 حوامل فوق 40 سنة + VTE: | B28: =COUNTIFS(البيانات!T:T,">40",البيانات!AD:AD,"Yes") -> 10 | C28: حالة عالية الخطورة | F28: 3️⃣ | G28: للتحويل لـ KFCH: حدد 'عالي جداً - تحويل KFCH' في تصنيف المنسق
F29: 4️⃣ | G29: لإضافة بيانات جديدة: انسخها إلى ورقة 'البيانات'
F30: 5️⃣ | G30: الجمعة والسبت مستثناة من حساب أيام العمل
A32: 🔗 روابط سريعة للأوراق:
A33: 📊 توزيع_الإحالات | B33: 🏥 إحالات_جازان | C33: 🏥 إحالات_صبيا | D33: 🏥 إحالات_أبو_عريش | F33: 🏥 إحالات_صامطة | G33: 🏥 إحالات_بيش | H33: 🏥 إحالات_KFCH | I33: 🚨 الحالات_العاجلة | J33: 📋 تقييم_VTE | K33: 📁 البيانات | L33: 🧠 النظام_الذكي

Sheet النظام_الذكي
A1: 🏥 نظام الحمل عالي الخطورة الذكي - تجمع جازان الصحي 2026 | M1: ⚠️ الحالات الحرجة تُحال للمستشفى التابع للقطاع أولاً، ثم تُحوَّل لـ KFCH بعد التقييم
B3: إجمالي الحالات | D3: 🔴 VTE عالي | F3: ⚠️ تحتاج إحالة | H3: عمر > 40 | J3: ✅ Enoxaparin | M3: 📈 إحصائيات الإحالات
B4: =COUNTA(البيانات!V2:V1000) -> 264 | D4: =COUNTIF(البيانات!AD2:AD1000,"Yes") -> 45 | F4: =COUNTIFS(البيانات!AD2:AD1000,"Yes",البيانات!AE2:AE1000,"No") -> 27 | H4: =COUNTIF(البيانات!T2:T1000,">40") -> 21 | J4: =COUNTIFS(البيانات!AD2:AD1000,"Yes",البيانات!AE2:AE1000,"Yes") -> 18 | M4: المستوى | N4: العدد | O4: النسبة
M5: 🔴 حرج | N5: =COUNTIF(H8:H273,"🔴 حرج") -> 36 | O5: =IF(B4=0,"-",TEXT(N5/B4,"0%")) -> 14%
A6: 📊 نظام توقع الإحالات الذكي | M6: 🟠 عالي | N6: =COUNTIF(H8:H273,"🟠 عالي") -> 57 | O6: =IF(B4=0,"-",TEXT(N6/B4,"0%")) -> 22%
A7: # | B7: السجل المدني | C7: اسم المريضة | D7: العمر | E7: القطاع | F7: VTE | G7: نقاط الخطورة | H7: مستوى الخطر | I7: توصية الإحالة | J7: الحالة | K7: الأولوية | L7: مستشفى الإحالة | M7: 🟡 متوسط | N7: =COUNTIF(H8:H273,"🟡 متوسط") -> 63 | O7: =IF(B4=0,"-",TEXT(N7/B4,"0%")) -> 24%
A8: 1 | B8: 1079626162 | C8: فايزة يحى جابر المالكى | D8: 33 | E8: القطاع الأوسط Middle Sector | F8: 🟢 لا | G8: 2 | H8: 🟢 منخفض | I8: متابعة روتينية | K8: 4 | L8: متابعة في المركز | M8: 🟢 منخفض | N8: =COUNTIF(H8:H273,"🟢 منخفض") -> 108 | O8: =IF(B4=0,"-",TEXT(N8/B4,"0%")) -> 41%
A9: 2 | B9: 1096345218 | C9: AWATIF AHMED ABDULLAH HAKAMI | D9: 38 | E9: القطاع المركزي Central Sector | F9: 🟢 لا | G9: 1 | H9: 🟢 منخفض | I9: متابعة روتينية | K9: 4 | L9: متابعة في المركز
A10: 3 | B10: 1067876415 | C10: MUTIBAH FAYADH MUTAEN TUMAYHI | D10: 42 | E10: القطاع الغربي Western Sector | F10: 🟢 لا | G10: 6 | H10: 🟠 عالي | I10: إحالة تخصصية | K10: 2 | L10: مستشفى صبيا العام | M10: ⚡ ملخص سريع
A11: 4 | B11: 1108769298 | C11: منيرة خالد علي خبراني | D11: 26 | E11: القطاع الأوسط Middle Sector | F11: 🔴 نعم | G11: 9 | H11: 🔴 حرج | I11: إحالة فورية | J11: ✅ تم العلاج | K11: 1 | L11: مستشفى أبو عريش العام ⚠️ | M11: إحالة فورية مطلوبة | N11: =N5 -> 36
A12: 5 | B12: 1042803070 | C12: WUSHAYLAH MOFAREH BIN YAHYA MUFDI | D12: 39 | E12: القطاع الجبلي Aljabaly Sector | F12: 🟢 لا | G12: 3 | H12: 🟡 متوسط | I12: متابعة مكثفة | K12: 3 | L12: مستشفى صبيا العام | M12: إحالة تخصصية | N12: =N6 -> 57
A13: 6 | B13: 1076123767 | C13: LAILA ALI HUSSAIN KADI | D13: 40 | E13: القطاع الغربي Western Sector | F13: 🟢 لا | G13: 1 | H13: 🟢 منخفض | I13: متابعة روتينية | K13: 4 | L13: متابعة في المركز | M13: VTE بدون Enoxaparin | N13: =F4 -> 27
A14: 7 | B14: 1098883562 | C14: ندا عبدالله ناصر صالح يحي | D14: 39 | E14: القطاع الأوسط Middle Sector | F14: 🟢 لا | G14: 3 | H14: 🟡 متوسط | I14: متابعة مكثفة | K14: 3 | L14: مستشفى أبو عريش العام | M14: متابعة مكثفة | N14: =N7 -> 63
A15: 8 | B15: 1110869045 | C15: هند جابر احمد عقيلي | D15: 33 | E15: القطاع المركزي Central Sector | F15: 🟢 لا | G15: 0 | H15: 🟢 منخفض | I15: متابعة روتينية | K15: 4 | L15: متابعة في المركز
A16: 9 | B16: 1131498006 | C16: KHADEJA AHMED ALI SARWI | D16: 34 | E16: القطاع الأوسط Middle Sector | F16: 🟢 لا | G16: 2 | H16: 🟢 منخفض | I16: متابعة روتينية | K16: 4 | L16: متابعة في المركز | M16: 🔍 البحث بالسجل المدني
A17: 10 | B17: 1060748751 | C17: رقيا احمد قاسم مجلي | D17: 47 | E17: القطاع الجبلي Aljabaly Sector | F17: 🟢 لا | G17: 7 | H17: 🟠 عالي | I17: إحالة تخصصية | K17: 2 | L17: مستشفى صبيا العام | M17: أدخل السجل المدني:
A18: 11 | B18: 1083600526 | C18: laila zowalan hawas | D18: 39 | E18: القطاع الجبلي Aljabaly Sector | F18: 🟢 لا | G18: 3 | H18: 🟡 متوسط | I18: متابعة مكثفة | K18: 3 | L18: مستشفى صبيا العام | M18: الاسم: | N18: =IF(N17="","أدخل السجل المدني",IFERROR(_xlfn.XLOOKUP(TEXT(N17,"0"),البيانات!V:V,البيانات!U:U),IFERROR(_xlfn.XLOOKUP(N17,البيانات!V:V,البيانات!U:U),"غير موجود"))) -> أدخل السجل المدني
A19: 12 | B19: 1102804414 | C19: عفراء حيدر عبده حكمي | D19: 29 | E19: القطاع المركزي Central Sector | F19: 🟢 لا | G19: 2 | H19: 🟢 منخفض | I19: متابعة روتينية | K19: 4 | L19: متابعة في المركز | M19: العمر: | N19: =IF(N17="","-",IFERROR(_xlfn.XLOOKUP(TEXT(N17,"0"),البيانات!V:V,البيانات!T:T),IFERROR(_xlfn.XLOOKUP(N17,البيانات!V:V,البيانات!T:T),"-"))) -> -
A20: 13 | B20: 1110832035 | C20: LAILA JABER ALI ADLAN | D20: 26 | E20: القطاع الغربي Western Sector | F20: 🟢 لا | G20: 2 | H20: 🟢 منخفض | I20: متابعة روتينية | K20: 4 | L20: متابعة في المركز | M20: القطاع: | N20: =IF(N17="","-",IFERROR(_xlfn.XLOOKUP(TEXT(N17,"0"),البيانات!V:V,البيانات!F:F),IFERROR(_xlfn.XLOOKUP(N17,البيانات!V:V,البيانات!F:F),"-"))) -> -
A21: 14 | B21: 1012673784 | C21: خجة محمد حكمي | D21: 43 | E21: القطاع المركزي Central Sector | F21: 🔴 نعم | G21: 11 | H21: 🔴 حرج | I21: إحالة فورية | J21: ✅ تم العلاج | K21: 1 | L21: مستشفى جازان العام ⚠️ | M21: VTE: | N21: =IF(N17="","-",IFERROR(IF(_xlfn.XLOOKUP(TEXT(N17,"0"),البيانات!V:V,البيانات!AD:AD)="Yes","🔴 نعم","🟢 لا"),IFERROR(IF(_xlfn.XLOOKUP(N17,البيانات!V:V,البيانات!AD:AD)="Yes","🔴 نعم","🟢 لا"),"-"))) -> -
A22: 15 | B22: 1085003786 | C22: فاطمة علي حكمي | D22: 32 | E22: القطاع المركزي Central Sector | F22: 🔴 نعم | G22: 7 | H22: 🟠 عالي | I22: إحالة تخصصية | J22: ⚠️ بدون علاج | K22: 2 | L22: مستشفى جازان العام | M22: نقاط الخطورة: | N22: {=IF(N17="","-",IFERROR(_xlfn.XLOOKUP(N17*1,B8:B166,G8:G166),IFERROR(_xlfn.XLOOKUP(TEXT(N17,"0"),TEXT(B8:B166,"0"),G8:G166),"-")))} -> -
A23: 16 | B23: 1115449041 | C23: BASMAH ABED ABDULLAH MASMALI | D23: 24 | E23: القطاع الأوسط Middle Sector | F23: 🟢 لا | G23: 0 | H23: 🟢 منخفض | I23: متابعة روتينية | K23: 4 | L23: متابعة في المركز | M23: مستوى الخطر: | N23: {=IF(N17="","-",IFERROR(_xlfn.XLOOKUP(N17*1,B8:B166,H8:H166),IFERROR(_xlfn.XLOOKUP(TEXT(N17,"0"),TEXT(B8:B166,"0"),H8:H166),"-")))} -> -
A24: 17 | B24: 1064754193 | C24: اميرة حسن عيسى حكمي | D24: 36 | E24: القطاع المركزي Central Sector | F24: 🟢 لا | G24: 3 | H24: 🟡 متوسط | I24: متابعة مكثفة | K24: 3 | L24: مستشفى جازان العام | M24: التوصية: | N24: {=IF(N17="","-",IFERROR(_xlfn.XLOOKUP(N17*1,B8:B166,I8:I166),IFERROR(_xlfn.XLOOKUP(TEXT(N17,"0"),TEXT(B8:B166,"0"),I8:I166),"-")))} -> -
A25: 18 | B25: 1098360264 | C25: AMAL MUSHARI ALKHAIRAT | D25: 29 | E25: القطاع المركزي Central Sector | F25: 🟢 لا | G25: 3 | H25: 🟡 متوسط | I25: متابعة مكثفة | K25: 3 | L25: مستشفى جازان العام
A26: 19 | B26: 1081663989 | C26: هدي منصور عبده حمدي | D26: 33 | E26: القطاع الجنوبي Southern Sector | F26: 🟢 لا | G26: 0 | H26: 🟢 منخفض | I26: متابعة روتينية | K26: 4 | L26: متابعة في المركز | M26: 📋 تعليمات الاستخدام
A27: 20 | B27: 1084038429 | C27: FATIMAH MOHAMMED HAMAD HAKAMI | D27: 42 | E27: القطاع المركزي Central Sector | F27: 🟢 لا | G27: 11 | H27: 🔴 حرج | I27: إحالة فورية | K27: 1 | L27: مستشفى جازان العام ⚠️ | M27: 1. البيانات تتحدث تلقائياً من ورقة البيانات
A28: 21 | B28: 1096237886 | C28: هناء حسن النعمي | D28: 36 | E28: القطاع الأوسط Middle Sector | F28: 🔴 نعم | G28: 8 | H28: 🔴 حرج | I28: إحالة فورية | J28: ✅ تم العلاج | K28: 1 | L28: مستشفى أبو عريش العام ⚠️ | M28: 2. للبحث: أدخل السجل المدني في الخانة الصفراء
A29: 22 | B29: 1077958971 | C29: fatma jaber mohammed | D29: 34 | E29: القطاع الشمالي Northern Sector | F29: 🔴 نعم | G29: 7 | H29: 🟠 عالي | I29: إحالة تخصصية | J29: ⚠️ بدون علاج | K29: 2 | L29: مستشفى بيش العام | M29: 3. الحالات الحرجة تظهر باللون الأحمر
A30: 23 | B30: 1133657294 | C30: سهام علي علي عتين | D30: 27 | E30: القطاع الجنوبي Southern Sector | F30: 🟢 لا | G30: 2 | H30: 🟢 منخفض | I30: متابعة روتينية | K30: 4 | L30: متابعة في المركز | M30: 4. ⚠️ بدون علاج = تحتاج Enoxaparin فوراً
A31: 24 | B31: 1073801175 | C31: RYHANA AHMED JABBAR | D31: 38 | E31: القطاع الشمالي Northern Sector | F31: 🟢 لا | G31: 3 | H31: 🟡 متوسط | I31: متابعة مكثفة | K31: 3 | L31: مستشفى بيش العام | M31: 5. للفرز: اضغط على عمود الأولوية (K)
A32: 25 | B32: 1129763536 | C32: نعمه احمد سليمان علي غزواني | D32: 20 | E32: القطاع الجبلي Aljabaly Sector | F32: 🟢 لا | G32: 0 | H32: 🟢 منخفض | I32: متابعة روتينية | K32: 4 | L32: متابعة في المركز
A33: 26 | B33: 1100678240 | C33: لطيفه علي موسى حيدر | D33: 28 | E33: القطاع الغربي Western Sector | F33: 🟢 لا | G33: 0 | H33: 🟢 منخفض | I33: متابعة روتينية | K33: 4 | L33: متابعة في المركز
A34: 27 | B34: 2500917717 | C34: Aesha MOHAMMED AHMED MURAYR | D34: 26 | E34: القطاع الغربي Western Sector | F34: 🟢 لا | G34: 0 | H34: 🟢 منخفض | I34: متابعة روتينية | K34: 4 | L34: متابعة في المركز
A35: 28 | B35: 1065088799 | C35: سهام احمد حسن مسملي | D35: 42 | E35: القطاع المركزي Central Sector | F35: 🔴 نعم | G35: 13 | H35: 🔴 حرج | I35: إحالة فورية | J35: ✅ تم العلاج | K35: 1 | L35: مستشفى جازان العام ⚠️
A36: 29 | B36: 1099873398 | C36: SHYMAA EISAA ALI | D36: 38 | E36: القطاع المركزي Central Sector | F36: 🔴 نعم | G36: 6 | H36: 🟠 عالي | I36: إحالة تخصصية | J36: ✅ تم العلاج | K36: 2 | L36: مستشفى جازان العام
A37: 30 | B37: 1112003148 | C37: ZARAH MOFAREH ALI SUHLULI | D37: 24 | E37: القطاع الغربي Western Sector | F37: 🟢 لا | G37: 2 | H37: 🟢 منخفض | I37: متابعة روتينية | K37: 4 | L37: متابعة في المركز
A38: 31 | B38: 1078175161 | C38: Nada bahlul yahya kurmi | D38: 36 | E38: القطاع الأوسط Middle Sector | F38: 🟢 لا | G38: 3 | H38: 🟡 متوسط | I38: متابعة مكثفة | K38: 3 | L38: مستشفى أبو عريش العام
A39: 32 | B39: 1103541114 | C39: RADHYAH YAHYA MOHAMMED ALMALKI | D39: 27 | E39: القطاع المركزي Central Sector | F39: 🟢 لا | G39: 0 | H39: 🟢 منخفض | I39: متابعة روتينية | K39: 4 | L39: متابعة في المركز
A40: 33 | B40: 1118015930 | C40: NORAH HUSSAIN OTHMAN HAKAMI | D40: 36 | E40: القطاع المركزي Central Sector | F40: 🟢 لا | G40: 1 | H40: 🟢 منخفض | I40: متابعة روتينية | K40: 4 | L40: متابعة في المركز
A41: 34 | B41: 1068377900 | C41: SALIHAH AHMED HUSSAIN GHAZWANI | D41: 35 | E41: القطاع المركزي Central Sector | F41: 🟢 لا | G41: 2 | H41: 🟢 منخفض | I41: متابعة روتينية | K41: 4 | L41: متابعة في المركز
...

Sheet إحالات_KFCH
A1: 🏥 مستشفى الملك فهد المركزي - قائمة الإحالات (تلقائي من البيانات)
B2: {=SUMPRODUCT((ISNUMBER(SEARCH("فهد",البيانات!$AS$2:$AS$300)))*1)} -> 1
A3: ✅ هذه الورقة تسحب تلقائياً الحالات المسجلة لمستشفى الملك فهد من عمود 'اسم المستشفى المحال إليه' في ورقة البيانات
A5: # | B5: السجل المدني | C5: اسم المريضة | D5: العمر | E5: القطاع | F5: رقم الجوال | G5: مستوى الخطر | H5: توصية الإحالة | I5: تاريخ الزيارة | J5: تاريخ الموعد | K5: الالتزام | L5: افادة الحضور | M5: تصنيف المنسق | N5: ملاحظات المنسق
A7: 1 | B7: {=IFERROR(INDEX(_xlfn._xlws.FILTER(البيانات!$V:$V,ISNUMBER(SEARCH("فهد",البيانات!$AS:$AS))),ROW()-6),"")} -> 1108769298 | C7: {=IFERROR(INDEX(_xlfn._xlws.FILTER(البيانات!$U:$U,ISNUMBER(SEARCH("فهد",البيانات!$AS:$AS))),ROW()-6),"")} -> منيرة خالد علي خبراني | D7: {=IFERROR(INDEX(_xlfn._xlws.FILTER(البيانات!$T:$T,ISNUMBER(SEARCH("فهد",البيانات!$AS:$AS))),ROW()-6),"")} -> 26 | E7: {=IFERROR(INDEX(_xlfn._xlws.FILTER(البيانات!$F:$F,ISNUMBER(SEARCH("فهد",البيانات!$AS:$AS))),ROW()-6),"")} -> القطاع الأوسط Middle Sector | F7: {=IFERROR(INDEX(_xlfn._xlws.FILTER(البيانات!$Y:$Y,ISNUMBER(SEARCH("فهد",البيانات!$AS:$AS))),ROW()-6),"")} -> 0551309299 | I7: {=IFERROR(INDEX(_xlfn._xlws.FILTER(البيانات!$P:$P,ISNUMBER(SEARCH("فهد",البيانات!$AS:$AS))),ROW()-6),"")} -> 46113 | J7: {=IFERROR(INDEX(_xlfn._xlws.FILTER(البيانات!$AI:$AI,ISNUMBER(SEARCH("فهد",البيانات!$AS:$AS))),ROW()-6),"")} -> 46117 | K7: =IF(OR(I7="",J7=""),"",IF(NETWORKDAYS.INTL(I7,J7,"0000011")-1<=2,"✅ ملتزم","❌ غير ملتزم")) -> ✅ ملتزم | L7: {=IFERROR(INDEX(_xlfn._xlws.FILTER(البيانات!$AJ:$AJ,ISNUMBER(SEARCH("فهد",البيانات!$AS:$AS))),ROW()-6),"")} -> حضرت
A8: 2 | B8: {=IFERROR(INDEX(_xlfn._xlws.FILTER(البيانات!$V:$V,ISNUMBER(SEARCH("فهد",البيانات!$AS:$AS))),2),"")} | C8: {=IFERROR(INDEX(_xlfn._xlws.FILTER(البيانات!$U:$U,ISNUMBER(SEARCH("فهد",البيانات!$AS:$AS))),2),"")} | D8: {=IFERROR(INDEX(_xlfn._xlws.FILTER(البيانات!$T:$T,ISNUMBER(SEARCH("فهد",البيانات!$AS:$AS))),2),"")} | E8: {=IFERROR(INDEX(_xlfn._xlws.FILTER(البيانات!$F:$F,ISNUMBER(SEARCH("فهد",البيانات!$AS:$AS))),2),"")} | F8: {=IFERROR(INDEX(_xlfn._xlws.FILTER(البيانات!$Y:$Y,ISNUMBER(SEARCH("فهد",البيانات!$AS:$AS))),2),"")} | I8: {=IFERROR(INDEX(_xlfn._xlws.FILTER(البيانات!$P:$P,ISNUMBER(SEARCH("فهد",البيانات!$AS:$AS))),2),"")} | J8: {=IFERROR(INDEX(_xlfn._xlws.FILTER(البيانات!$AI:$AI,ISNUMBER(SEARCH("فهد",البيانات!$AS:$AS))),2),"")} | K8: =IF(OR(I8="",J8=""),"⏳ بانتظار",IF(NETWORKDAYS.INTL(I8,J8,"0000011")-1<=2,"✅ ملتزم","❌ غير ملتزم")) -> ⏳ بانتظار | L8: {=IFERROR(INDEX(_xlfn._xlws.FILTER(البيانات!$AJ:$AJ,ISNUMBER(SEARCH("فهد",البيانات!$AS:$AS))),2),"")}
A9: 3 | B9: {=IFERROR(INDEX(_xlfn._xlws.FILTER(البيانات!$V:$V,ISNUMBER(SEARCH("فهد",البيانات!$AS:$AS))),3),"")} | C9: {=IFERROR(INDEX(_xlfn._xlws.FILTER(البيانات!$U:$U,ISNUMBER(SEARCH("فهد",البيانات!$AS:$AS))),3),"")} | D9: {=IFERROR(INDEX(_xlfn._xlws.FILTER(البيانات!$T:$T,ISNUMBER(SEARCH("فهد",البيانات!$AS:$AS))),3),"")} | E9: {=IFERROR(INDEX(_xlfn._xlws.FILTER(البيانات!$F:$F,ISNUMBER(SEARCH("فهد",البيانات!$AS:$AS))),3),"")} | F9: {=IFERROR(INDEX(_xlfn._xlws.FILTER(البيانات!$Y:$Y,ISNUMBER(SEARCH("فهد",البيانات!$AS:$AS))),3),"")} | I9: {=IFERROR(INDEX(_xlfn._xlws.FILTER(البيانات!$P:$P,ISNUMBER(SEARCH("فهد",البيانات!$AS:$AS))),3),"")} | J9: {=IFERROR(INDEX(_xlfn._xlws.FILTER(البيانات!$AI:$AI,ISNUMBER(SEARCH("فهد",البيانات!$AS:$AS))),3),"")} | K9: =IF(OR(I9="",J9=""),"⏳ بانتظار",IF(NETWORKDAYS.INTL(I9,J9,"0000011")-1<=2,"✅ ملتزم","❌ غير ملتزم")) -> ⏳ بانتظار | L9: {=IFERROR(INDEX(_xlfn._xlws.FILTER(البيانات!$AJ:$AJ,ISNUMBER(SEARCH("فهد",البيانات!$AS:$AS))),3),"")}
A10: 4 | B10: {=IFERROR(INDEX(_xlfn._xlws.FILTER(البيانات!$V:$V,ISNUMBER(SEARCH("فهد",البيانات!$AS:$AS))),4),"")} | C10: {=IFERROR(INDEX(_xlfn._xlws.FILTER(البيانات!$U:$U,ISNUMBER(SEARCH("فهد",البيانات!$AS:$AS))),4),"")} | D10: {=IFERROR(INDEX(_xlfn._xlws.FILTER(البيانات!$T:$T,ISNUMBER(SEARCH("فهد",البيانات!$AS:$AS))),4),"")} | E10: {=IFERROR(INDEX(_xlfn._xlws.FILTER(البيانات!$F:$F,ISNUMBER(SEARCH("فهد",البيانات!$AS:$AS))),4),"")} | F10: {=IFERROR(INDEX(_xlfn._xlws.FILTER(البيانات!$Y:$Y,ISNUMBER(SEARCH("فهد",البيانات!$AS:$AS))),4),"")} | I10: {=IFERROR(INDEX(_xlfn._xlws.FILTER(البيانات!$P:$P,ISNUMBER(SEARCH("فهد",البيانات!$AS:$AS))),4),"")} | J10: {=IFERROR(INDEX(_xlfn._xlws.FILTER(البيانات!$AI:$AI,ISNUMBER(SEARCH("فهد",البيانات!$AS:$AS))),4),"")} | K10: =IF(OR(I10="",J10=""),"⏳ بانتظار",IF(NETWORKDAYS.INTL(I10,J10,"0000011")-1<=2,"✅ ملتزم","❌ غير ملتزم")) -> ⏳ بانتظار | L10: {=IFERROR(INDEX(_xlfn._xlws.FILTER(البيانات!$AJ:$AJ,ISNUMBER(SEARCH("فهد",البيانات!$AS:$AS))),4),"")}
A11: 5 | B11: {=IFERROR(INDEX(_xlfn._xlws.FILTER(البيانات!$V:$V,ISNUMBER(SEARCH("فهد",البيانات!$AS:$AS))),5),"")} | C11: {=IFERROR(INDEX(_xlfn._xlws.FILTER(البيانات!$U:$U,ISNUMBER(SEARCH("فهد",البيانات!$AS:$AS))),5),"")} | D11: {=IFERROR(INDEX(_xlfn._xlws.FILTER(البيانات!$T:$T,ISNUMBER(SEARCH("فهد",البيانات!$AS:$AS))),5),"")} | E11: {=IFERROR(INDEX(_xlfn._xlws.FILTER(البيانات!$F:$F,ISNUMBER(SEARCH("فهد",البيانات!$AS:$AS))),5),"")} | F11: {=IFERROR(INDEX(_xlfn._xlws.FILTER(البيانات!$Y:$Y,ISNUMBER(SEARCH("فهد",البيانات!$AS:$AS))),5),"")} | I11: {=IFERROR(INDEX(_xlfn._xlws.FILTER(البيانات!$P:$P,ISNUMBER(SEARCH("فهد",البيانات!$AS:$AS))),5),"")} | J11: {=IFERROR(INDEX(_xlfn._xlws.FILTER(البيانات!$AI:$AI,ISNUMBER(SEARCH("فهد",البيانات!$AS:$AS))),5),"")} | K11: =IF(OR(I11="",J11=""),"⏳ بانتظار",IF(NETWORKDAYS.INTL(I11,J11,"0000011")-1<=2,"✅ ملتزم","❌ غير ملتزم")) -> ⏳ بانتظار | L11: {=IFERROR(INDEX(_xlfn._xlws.FILTER(البيانات!$AJ:$AJ,ISNUMBER(SEARCH("فهد",البيانات!$AS:$AS))),5),"")}
A12: 6 | B12: {=IFERROR(INDEX(_xlfn._xlws.FILTER(البيانات!$V:$V,ISNUMBER(SEARCH("فهد",البيانات!$AS:$AS))),6),"")} | C12: {=IFERROR(INDEX(_xlfn._xlws.FILTER(البيانات!$U:$U,ISNUMBER(SEARCH("فهد",البيانات!$AS:$AS))),6),"")} | D12: {=IFERROR(INDEX(_xlfn._xlws.FILTER(البيانات!$T:$T,ISNUMBER(SEARCH("فهد",البيانات!$AS:$AS))),6),"")} | E12: {=IFERROR(INDEX(_xlfn._xlws.FILTER(البيانات!$F:$F,ISNUMBER(SEARCH("فهد",البيانات!$AS:$AS))),6),"")} | F12: {=IFERROR(INDEX(_xlfn._xlws.FILTER(البيانات!$Y:$Y,ISNUMBER(SEARCH("فهد",البيانات!$AS:$AS))),6),"")} | I12: {=IFERROR(INDEX(_xlfn._xlws.FILTER(البيانات!$P:$P,ISNUMBER(SEARCH("فهد",البيانات!$AS:$AS))),6),"")} | J12: {=IFERROR(INDEX(_xlfn._xlws.FILTER(البيانات!$AI:$AI,ISNUMBER(SEARCH("فهد",البيانات!$AS:$AS))),6),"")} | K12: =IF(OR(I12="",J12=""),"⏳ بانتظار",IF(NETWORKDAYS.INTL(I12,J12,"0000011")-1<=2,"✅ ملتزم","❌ غير ملتزم")) -> ⏳ بانتظار | L12: {=IFERROR(INDEX(_xlfn._xlws.FILTER(البيانات!$AJ:$AJ,ISNUMBER(SEARCH("فهد",البيانات!$AS:$AS))),6),"")}
A13: 7 | B13: {=IFERROR(INDEX(_xlfn._xlws.FILTER(البيانات!$V:$V,ISNUMBER(SEARCH("فهد",البيانات!$AS:$AS))),7),"")} | C13: {=IFERROR(INDEX(_xlfn._xlws.FILTER(البيانات!$U:$U,ISNUMBER(SEARCH("فهد",البيانات!$AS:$AS))),7),"")} | D13: {=IFERROR(INDEX(_xlfn._xlws.FILTER(البيانات!$T:$T,ISNUMBER(SEARCH("فهد",البيانات!$AS:$AS))),7),"")} | E13: {=IFERROR(INDEX(_xlfn._xlws.FILTER(البيانات!$F:$F,ISNUMBER(SEARCH("فهد",البيانات!$AS:$AS))),7),"")} | F13: {=IFERROR(INDEX(_xlfn._xlws.FILTER(البيانات!$Y:$Y,ISNUMBER(SEARCH("فهد",البيانات!$AS:$AS))),7),"")} | I13: {=IFERROR(INDEX(_xlfn._xlws.FILTER(البيانات!$P:$P,ISNUMBER(SEARCH("فهد",البيانات!$AS:$AS))),7),"")} | J13: {=IFERROR(INDEX(_xlfn._xlws.FILTER(البيانات!$AI:$AI,ISNUMBER(SEARCH("فهد",البيانات!$AS:$AS))),7),"")} | K13: =IF(OR(I13="",J13=""),"⏳ بانتظار",IF(NETWORKDAYS.INTL(I13,J13,"0000011")-1<=2,"✅ ملتزم","❌ غير ملتزم")) -> ⏳ بانتظار | L13: {=IFERROR(INDEX(_xlfn._xlws.FILTER(البيانات!$AJ:$AJ,ISNUMBER(SEARCH("فهد",البيانات!$AS:$AS))),7),"")}
A14: 8 | B14: {=IFERROR(INDEX(_xlfn._xlws.FILTER(البيانات!$V:$V,ISNUMBER(SEARCH("فهد",البيانات!$AS:$AS))),8),"")} | C14: {=IFERROR(INDEX(_xlfn._xlws.FILTER(البيانات!$U:$U,ISNUMBER(SEARCH("فهد",البيانات!$AS:$AS))),8),"")} | D14: {=IFERROR(INDEX(_xlfn._xlws.FILTER(البيانات!$T:$T,ISNUMBER(SEARCH("فهد",البيانات!$AS:$AS))),8),"")} | E14: {=IFERROR(INDEX(_xlfn._xlws.FILTER(البيانات!$F:$F,ISNUMBER(SEARCH("فهد",البيانات!$AS:$AS))),8),"")} | F14: {=IFERROR(INDEX(_xlfn._xlws.FILTER(البيانات!$Y:$Y,ISNUMBER(SEARCH("فهد",البيانات!$AS:$AS))),8),"")} | I14: {=IFERROR(INDEX(_xlfn._xlws.FILTER(البيانات!$P:$P,ISNUMBER(SEARCH("فهد",البيانات!$AS:$AS))),8),"")} | J14: {=IFERROR(INDEX(_xlfn._xlws.FILTER(البيانات!$AI:$AI,ISNUMBER(SEARCH("فهد",البيانات!$AS:$AS))),8),"")} | K14: =IF(OR(I14="",J14=""),"⏳ بانتظار",IF(NETWORKDAYS.INTL(I14,J14,"0000011")-1<=2,"✅ ملتزم","❌ غير ملتزم")) -> ⏳ بانتظار | L14: {=IFERROR(INDEX(_xlfn._xlws.FILTER(البيانات!$AJ:$AJ,ISNUMBER(SEARCH("فهد",البيانات!$AS:$AS))),8),"")}
A15: 9 | B15: {=IFERROR(INDEX(_xlfn._xlws.FILTER(البيانات!$V:$V,ISNUMBER(SEARCH("فهد",البيانات!$AS:$AS))),9),"")} | C15: {=IFERROR(INDEX(_xlfn._xlws.FILTER(البيانات!$U:$U,ISNUMBER(SEARCH("فهد",البيانات!$AS:$AS))),9),"")} | D15: {=IFERROR(INDEX(_xlfn._xlws.FILTER(البيانات!$T:$T,ISNUMBER(SEARCH("فهد",البيانات!$AS:$AS))),9),"")} | E15: {=IFERROR(INDEX(_xlfn._xlws.FILTER(البيانات!$F:$F,ISNUMBER(SEARCH("فهد",البيانات!$AS:$AS))),9),"")} | F15: {=IFERROR(INDEX(_xlfn._xlws.FILTER(البيانات!$Y:$Y,ISNUMBER(SEARCH("فهد",البيانات!$AS:$AS))),9),"")} | I15: {=IFERROR(INDEX(_xlfn._xlws.FILTER(البيانات!$P:$P,ISNUMBER(SEARCH("فهد",البيانات!$AS:$AS))),9),"")} | J15: {=IFERROR(INDEX(_xlfn._xlws.FILTER(البيانات!$AI:$AI,ISNUMBER(SEARCH("فهد",البيانات!$AS:$AS))),9),"")} | K15: =IF(OR(I15="",J15=""),"⏳ بانتظار",IF(NETWORKDAYS.INTL(I15,J15,"0000011")-1<=2,"✅ ملتزم","❌ غير ملتزم")) -> ⏳ بانتظار | L15: {=IFERROR(INDEX(_xlfn._xlws.FILTER(البيانات!$AJ:$AJ,ISNUMBER(SEARCH("فهد",البيانات!$AS:$AS))),9),"")}
A16: 10 | B16: {=IFERROR(INDEX(_xlfn._xlws.FILTER(البيانات!$V:$V,ISNUMBER(SEARCH("فهد",البيانات!$AS:$AS))),10),"")} | C16: {=IFERROR(INDEX(_xlfn._xlws.FILTER(البيانات!$U:$U,ISNUMBER(SEARCH("فهد",البيانات!$AS:$AS))),10),"")} | D16: {=IFERROR(INDEX(_xlfn._xlws.FILTER(البيانات!$T:$T,ISNUMBER(SEARCH("فهد",البيانات!$AS:$AS))),10),"")} | E16: {=IFERROR(INDEX(_xlfn._xlws.FILTER(البيانات!$F:$F,ISNUMBER(SEARCH("فهد",البيانات!$AS:$AS))),10),"")} | F16: {=IFERROR(INDEX(_xlfn._xlws.FILTER(البيانات!$Y:$Y,ISNUMBER(SEARCH("فهد",البيانات!$AS:$AS))),10),"")} | I16: {=IFERROR(INDEX(_xlfn._xlws.FILTER(البيانات!$P:$P,ISNUMBER(SEARCH("فهد",البيانات!$AS:$AS))),10),"")} | J16: {=IFERROR(INDEX(_xlfn._xlws.FILTER(البيانات!$AI:$AI,ISNUMBER(SEARCH("فهد",البيانات!$AS:$AS))),10),"")} | K16: =IF(OR(I16="",J16=""),"⏳ بانتظار",IF(NETWORKDAYS.INTL(I16,J16,"0000011")-1<=2,"✅ ملتزم","❌ غير ملتزم")) -> ⏳ بانتظار | L16: {=IFERROR(INDEX(_xlfn._xlws.FILTER(البيانات!$AJ:$AJ,ISNUMBER(SEARCH("فهد",البيانات!$AS:$AS))),10),"")}
A17: 11 | B17: {=IFERROR(INDEX(البيانات!$V$2:$V$500,SMALL(IF((ISNUMBER(SEARCH("فهد",البيانات!$AM$2:$AM$500))+ISNUMBER(SEARCH("KFCH",البيانات!$AM$2:$AM$500)))>0,ROW(البيانات!$V$2:$V$500)-ROW(البيانات!$V$2)+1),11)),"")} | C17: {=IFERROR(INDEX(البيانات!$U$2:$U$500,SMALL(IF((ISNUMBER(SEARCH("فهد",البيانات!$AM$2:$AM$500))+ISNUMBER(SEARCH("KFCH",البيانات!$AM$2:$AM$500)))>0,ROW(البيانات!$U$2:$U$500)-ROW(البيانات!$U$2)+1),11)),"")} | D17: {=IFERROR(INDEX(البيانات!$T$2:$T$500,SMALL(IF((ISNUMBER(SEARCH("فهد",البيانات!$AM$2:$AM$500))+ISNUMBER(SEARCH("KFCH",البيانات!$AM$2:$AM$500)))>0,ROW(البيانات!$T$2:$T$500)-ROW(البيانات!$T$2)+1),11)),"")} | E17: {=IFERROR(INDEX(البيانات!$F$2:$F$500,SMALL(IF((ISNUMBER(SEARCH("فهد",البيانات!$AM$2:$AM$500))+ISNUMBER(SEARCH("KFCH",البيانات!$AM$2:$AM$500)))>0,ROW(البيانات!$F$2:$F$500)-ROW(البيانات!$F$2)+1),11)),"")} | F17: {=IFERROR(INDEX(البيانات!$Y$2:$Y$500,SMALL(IF((ISNUMBER(SEARCH("فهد",البيانات!$AM$2:$AM$500))+ISNUMBER(SEARCH("KFCH",البيانات!$AM$2:$AM$500)))>0,ROW(البيانات!$Y$2:$Y$500)-ROW(البيانات!$Y$2)+1),11)),"")} | I17: {=IFERROR(INDEX(البيانات!$P$2:$P$500,SMALL(IF((ISNUMBER(SEARCH("فهد",البيانات!$AM$2:$AM$500))+ISNUMBER(SEARCH("KFCH",البيانات!$AM$2:$AM$500)))>0,ROW(البيانات!$P$2:$P$500)-ROW(البيانات!$P$2)+1),11)),"")} | J17: {=IFERROR(INDEX(البيانات!$AI$2:$AI$500,SMALL(IF((ISNUMBER(SEARCH("فهد",البيانات!$AM$2:$AM$500))+ISNUMBER(SEARCH("KFCH",البيانات!$AM$2:$AM$500)))>0,ROW(البيانات!$AI$2:$AI$500)-ROW(البيانات!$AI$2)+1),11)),"")} | K17: =IF(OR(I17="",J17=""),"",IF(NETWORKDAYS.INTL(I17,J17,"0000011")-1<=2,"✅ ملتزم","❌ غير ملتزم")) | L17: {=IFERROR(INDEX(البيانات!$AJ$2:$AJ$500,SMALL(IF((ISNUMBER(SEARCH("فهد",البيانات!$AM$2:$AM$500))+ISNUMBER(SEARCH("KFCH",البيانات!$AM$2:$AM$500)))>0,ROW(البيانات!$AJ$2:$AJ$500)-ROW(البيانات!$AJ$2)+1),11)),"")}
A18: 12 | B18: {=IFERROR(INDEX(البيانات!$V$2:$V$500,SMALL(IF((ISNUMBER(SEARCH("فهد",البيانات!$AM$2:$AM$500))+ISNUMBER(SEARCH("KFCH",البيانات!$AM$2:$AM$500)))>0,ROW(البيانات!$V$2:$V$500)-ROW(البيانات!$V$2)+1),12)),"")} | C18: {=IFERROR(INDEX(البيانات!$U$2:$U$500,SMALL(IF((ISNUMBER(SEARCH("فهد",البيانات!$AM$2:$AM$500))+ISNUMBER(SEARCH("KFCH",البيانات!$AM$2:$AM$500)))>0,ROW(البيانات!$U$2:$U$500)-ROW(البيانات!$U$2)+1),12)),"")} | D18: {=IFERROR(INDEX(البيانات!$T$2:$T$500,SMALL(IF((ISNUMBER(SEARCH("فهد",البيانات!$AM$2:$AM$500))+ISNUMBER(SEARCH("KFCH",البيانات!$AM$2:$AM$500)))>0,ROW(البيانات!$T$2:$T$500)-ROW(البيانات!$T$2)+1),12)),"")} | E18: {=IFERROR(INDEX(البيانات!$F$2:$F$500,SMALL(IF((ISNUMBER(SEARCH("فهد",البيانات!$AM$2:$AM$500))+ISNUMBER(SEARCH("KFCH",البيانات!$AM$2:$AM$500)))>0,ROW(البيانات!$F$2:$F$500)-ROW(البيانات!$F$2)+1),12)),"")} | F18: {=IFERROR(INDEX(البيانات!$Y$2:$Y$500,SMALL(IF((ISNUMBER(SEARCH("فهد",البيانات!$AM$2:$AM$500))+ISNUMBER(SEARCH("KFCH",البيانات!$AM$2:$AM$500)))>0,ROW(البيانات!$Y$2:$Y$500)-ROW(البيانات!$Y$2)+1),12)),"")} | I18: {=IFERROR(INDEX(البيانات!$P$2:$P$500,SMALL(IF((ISNUMBER(SEARCH("فهد",البيانات!$AM$2:$AM$500))+ISNUMBER(SEARCH("KFCH",البيانات!$AM$2:$AM$500)))>0,ROW(البيانات!$P$2:$P$500)-ROW(البيانات!$P$2)+1),12)),"")} | J18: {=IFERROR(INDEX(البيانات!$AI$2:$AI$500,SMALL(IF((ISNUMBER(SEARCH("فهد",البيانات!$AM$2:$AM$500))+ISNUMBER(SEARCH("KFCH",البيانات!$AM$2:$AM$500)))>0,ROW(البيانات!$AI$2:$AI$500)-ROW(البيانات!$AI$2)+1),12)),"")} | K18: =IF(OR(I18="",J18=""),"",IF(NETWORKDAYS.INTL(I18,J18,"0000011")-1<=2,"✅ ملتزم","❌ غير ملتزم")) | L18: {=IFERROR(INDEX(البيانات!$AJ$2:$AJ$500,SMALL(IF((ISNUMBER(SEARCH("فهد",البيانات!$AM$2:$AM$500))+ISNUMBER(SEARCH("KFCH",البيانات!$AM$2:$AM$500)))>0,ROW(البيانات!$AJ$2:$AJ$500)-ROW(البيانات!$AJ$2)+1),12)),"")}
A19: 13 | B19: {=IFERROR(INDEX(البيانات!$V$2:$V$500,SMALL(IF((ISNUMBER(SEARCH("فهد",البيانات!$AM$2:$AM$500))+ISNUMBER(SEARCH("KFCH",البيانات!$AM$2:$AM$500)))>0,ROW(البيانات!$V$2:$V$500)-ROW(البيانات!$V$2)+1),13)),"")} | C19: {=IFERROR(INDEX(البيانات!$U$2:$U$500,SMALL(IF((ISNUMBER(SEARCH("فهد",البيانات!$AM$2:$AM$500))+ISNUMBER(SEARCH("KFCH",البيانات!$AM$2:$AM$500)))>0,ROW(البيانات!$U$2:$U$500)-ROW(البيانات!$U$2)+1),13)),"")} | D19: {=IFERROR(INDEX(البيانات!$T$2:$T$500,SMALL(IF((ISNUMBER(SEARCH("فهد",البيانات!$AM$2:$AM$500))+ISNUMBER(SEARCH("KFCH",البيانات!$AM$2:$AM$500)))>0,ROW(البيانات!$T$2:$T$500)-ROW(البيانات!$T$2)+1),13)),"")} | E19: {=IFERROR(INDEX(البيانات!$F$2:$F$500,SMALL(IF((ISNUMBER(SEARCH("فهد",البيانات!$AM$2:$AM$500))+ISNUMBER(SEARCH("KFCH",البيانات!$AM$2:$AM$500)))>0,ROW(البيانات!$F$2:$F$500)-ROW(البيانات!$F$2)+1),13)),"")} | F19: {=IFERROR(INDEX(البيانات!$Y$2:$Y$500,SMALL(IF((ISNUMBER(SEARCH("فهد",البيانات!$AM$2:$AM$500))+ISNUMBER(SEARCH("KFCH",البيانات!$AM$2:$AM$500)))>0,ROW(البيانات!$Y$2:$Y$500)-ROW(البيانات!$Y$2)+1),13)),"")} | I19: {=IFERROR(INDEX(البيانات!$P$2:$P$500,SMALL(IF((ISNUMBER(SEARCH("فهد",البيانات!$AM$2:$AM$500))+ISNUMBER(SEARCH("KFCH",البيانات!$AM$2:$AM$500)))>0,ROW(البيانات!$P$2:$P$500)-ROW(البيانات!$P$2)+1),13)),"")} | J19: {=IFERROR(INDEX(البيانات!$AI$2:$AI$500,SMALL(IF((ISNUMBER(SEARCH("فهد",البيانات!$AM$2:$AM$500))+ISNUMBER(SEARCH("KFCH",البيانات!$AM$2:$AM$500)))>0,ROW(البيانات!$AI$2:$AI$500)-ROW(البيانات!$AI$2)+1),13)),"")} | K19: =IF(OR(I19="",J19=""),"",IF(NETWORKDAYS.INTL(I19,J19,"0000011")-1<=2,"✅ ملتزم","❌ غير ملتزم")) | L19: {=IFERROR(INDEX(البيانات!$AJ$2:$AJ$500,SMALL(IF((ISNUMBER(SEARCH("فهد",البيانات!$AM$2:$AM$500))+ISNUMBER(SEARCH("KFCH",البيانات!$AM$2:$AM$500)))>0,ROW(البيانات!$AJ$2:$AJ$500)-ROW(البيانات!$AJ$2)+1),13)),"")}
A20: 14 | B20: {=IFERROR(INDEX(البيانات!$V$2:$V$500,SMALL(IF((ISNUMBER(SEARCH("فهد",البيانات!$AM$2:$AM$500))+ISNUMBER(SEARCH("KFCH",البيانات!$AM$2:$AM$500)))>0,ROW(البيانات!$V$2:$V$500)-ROW(البيانات!$V$2)+1),14)),"")} | C20: {=IFERROR(INDEX(البيانات!$U$2:$U$500,SMALL(IF((ISNUMBER(SEARCH("فهد",البيانات!$AM$2:$AM$500))+ISNUMBER(SEARCH("KFCH",البيانات!$AM$2:$AM$500)))>0,ROW(البيانات!$U$2:$U$500)-ROW(البيانات!$U$2)+1),14)),"")} | D20: {=IFERROR(INDEX(البيانات!$T$2:$T$500,SMALL(IF((ISNUMBER(SEARCH("فهد",البيانات!$AM$2:$AM$500))+ISNUMBER(SEARCH("KFCH",البيانات!$AM$2:$AM$500)))>0,ROW(البيانات!$T$2:$T$500)-ROW(البيانات!$T$2)+1),14)),"")} | E20: {=IFERROR(INDEX(البيانات!$F$2:$F$500,SMALL(IF((ISNUMBER(SEARCH("فهد",البيانات!$AM$2:$AM$500))+ISNUMBER(SEARCH("KFCH",البيانات!$AM$2:$AM$500)))>0,ROW(البيانات!$F$2:$F$500)-ROW(البيانات!$F$2)+1),14)),"")} | F20: {=IFERROR(INDEX(البيانات!$Y$2:$Y$500,SMALL(IF((ISNUMBER(SEARCH("فهد",البيانات!$AM$2:$AM$500))+ISNUMBER(SEARCH("KFCH",البيانات!$AM$2:$AM$500)))>0,ROW(البيانات!$Y$2:$Y$500)-ROW(البيانات!$Y$2)+1),14)),"")} | I20: {=IFERROR(INDEX(البيانات!$P$2:$P$500,SMALL(IF((ISNUMBER(SEARCH("فهد",البيانات!$AM$2:$AM$500))+ISNUMBER(SEARCH("KFCH",البيانات!$AM$2:$AM$500)))>0,ROW(البيانات!$P$2:$P$500)-ROW(البيانات!$P$2)+1),14)),"")} | J20: {=IFERROR(INDEX(البيانات!$AI$2:$AI$500,SMALL(IF((ISNUMBER(SEARCH("فهد",البيانات!$AM$2:$AM$500))+ISNUMBER(SEARCH("KFCH",البيانات!$AM$2:$AM$500)))>0,ROW(البيانات!$AI$2:$AI$500)-ROW(البيانات!$AI$2)+1),14)),"")} | K20: =IF(OR(I20="",J20=""),"",IF(NETWORKDAYS.INTL(I20,J20,"0000011")-1<=2,"✅ ملتزم","❌ غير ملتزم")) | L20: {=IFERROR(INDEX(البيانات!$AJ$2:$AJ$500,SMALL(IF((ISNUMBER(SEARCH("فهد",البيانات!$AM$2:$AM$500))+ISNUMBER(SEARCH("KFCH",البيانات!$AM$2:$AM$500)))>0,ROW(البيانات!$AJ$2:$AJ$500)-ROW(البيانات!$AJ$2)+1),14)),"")}
A21: 15 | B21: {=IFERROR(INDEX(البيانات!$V$2:$V$500,SMALL(IF((ISNUMBER(SEARCH("فهد",البيانات!$AM$2:$AM$500))+ISNUMBER(SEARCH("KFCH",البيانات!$AM$2:$AM$500)))>0,ROW(البيانات!$V$2:$V$500)-ROW(البيانات!$V$2)+1),15)),"")} | C21: {=IFERROR(INDEX(البيانات!$U$2:$U$500,SMALL(IF((ISNUMBER(SEARCH("فهد",البيانات!$AM$2:$AM$500))+ISNUMBER(SEARCH("KFCH",البيانات!$AM$2:$AM$500)))>0,ROW(البيانات!$U$2:$U$500)-ROW(البيانات!$U$2)+1),15)),"")} | D21: {=IFERROR(INDEX(البيانات!$T$2:$T$500,SMALL(IF((ISNUMBER(SEARCH("فهد",البيانات!$AM$2:$AM$500))+ISNUMBER(SEARCH("KFCH",البيانات!$AM$2:$AM$500)))>0,ROW(البيانات!$T$2:$T$500)-ROW(البيانات!$T$2)+1),15)),"")} | E21: {=IFERROR(INDEX(البيانات!$F$2:$F$500,SMALL(IF((ISNUMBER(SEARCH("فهد",البيانات!$AM$2:$AM$500))+ISNUMBER(SEARCH("KFCH",البيانات!$AM$2:$AM$500)))>0,ROW(البيانات!$F$2:$F$500)-ROW(البيانات!$F$2)+1),15)),"")} | F21: {=IFERROR(INDEX(البيانات!$Y$2:$Y$500,SMALL(IF((ISNUMBER(SEARCH("فهد",البيانات!$AM$2:$AM$500))+ISNUMBER(SEARCH("KFCH",البيانات!$AM$2:$AM$500)))>0,ROW(البيانات!$Y$2:$Y$500)-ROW(البيانات!$Y$2)+1),15)),"")} | I21: {=IFERROR(INDEX(البيانات!$P$2:$P$500,SMALL(IF((ISNUMBER(SEARCH("فهد",البيانات!$AM$2:$AM$500))+ISNUMBER(SEARCH("KFCH",البيانات!$AM$2:$AM$500)))>0,ROW(البيانات!$P$2:$P$500)-ROW(البيانات!$P$2)+1),15)),"")} | J21: {=IFERROR(INDEX(البيانات!$AI$2:$AI$500,SMALL(IF((ISNUMBER(SEARCH("فهد",البيانات!$AM$2:$AM$500))+ISNUMBER(SEARCH("KFCH",البيانات!$AM$2:$AM$500)))>0,ROW(البيانات!$AI$2:$AI$500)-ROW(البيانات!$AI$2)+1),15)),"")} | K21: =IF(OR(I21="",J21=""),"",IF(NETWORKDAYS.INTL(I21,J21,"0000011")-1<=2,"✅ ملتزم","❌ غير ملتزم")) | L21: {=IFERROR(INDEX(البيانات!$AJ$2:$AJ$500,SMALL(IF((ISNUMBER(SEARCH("فهد",البيانات!$AM$2:$AM$500))+ISNUMBER(SEARCH("KFCH",البيانات!$AM$2:$AM$500)))>0,ROW(البيانات!$AJ$2:$AJ$500)-ROW(البيانات!$AJ$2)+1),15)),"")}
A22: 16 | B22: {=IFERROR(INDEX(البيانات!$V$2:$V$500,SMALL(IF((ISNUMBER(SEARCH("فهد",البيانات!$AM$2:$AM$500))+ISNUMBER(SEARCH("KFCH",البيانات!$AM$2:$AM$500)))>0,ROW(البيانات!$V$2:$V$500)-ROW(البيانات!$V$2)+1),16)),"")} | C22: {=IFERROR(INDEX(البيانات!$U$2:$U$500,SMALL(IF((ISNUMBER(SEARCH("فهد",البيانات!$AM$2:$AM$500))+ISNUMBER(SEARCH("KFCH",البيانات!$AM$2:$AM$500)))>0,ROW(البيانات!$U$2:$U$500)-ROW(البيانات!$U$2)+1),16)),"")} | D22: {=IFERROR(INDEX(البيانات!$T$2:$T$500,SMALL(IF((ISNUMBER(SEARCH("فهد",البيانات!$AM$2:$AM$500))+ISNUMBER(SEARCH("KFCH",البيانات!$AM$2:$AM$500)))>0,ROW(البيانات!$T$2:$T$500)-ROW(البيانات!$T$2)+1),16)),"")} | E22: {=IFERROR(INDEX(البيانات!$F$2:$F$500,SMALL(IF((ISNUMBER(SEARCH("فهد",البيانات!$AM$2:$AM$500))+ISNUMBER(SEARCH("KFCH",البيانات!$AM$2:$AM$500)))>0,ROW(البيانات!$F$2:$F$500)-ROW(البيانات!$F$2)+1),16)),"")} | F22: {=IFERROR(INDEX(البيانات!$Y$2:$Y$500,SMALL(IF((ISNUMBER(SEARCH("فهد",البيانات!$AM$2:$AM$500))+ISNUMBER(SEARCH("KFCH",البيانات!$AM$2:$AM$500)))>0,ROW(البيانات!$Y$2:$Y$500)-ROW(البيانات!$Y$2)+1),16)),"")} | I22: {=IFERROR(INDEX(البيانات!$P$2:$P$500,SMALL(IF((ISNUMBER(SEARCH("فهد",البيانات!$AM$2:$AM$500))+ISNUMBER(SEARCH("KFCH",البيانات!$AM$2:$AM$500)))>0,ROW(البيانات!$P$2:$P$500)-ROW(البيانات!$P$2)+1),16)),"")} | J22: {=IFERROR(INDEX(البيانات!$AI$2:$AI$500,SMALL(IF((ISNUMBER(SEARCH("فهد",البيانات!$AM$2:$AM$500))+ISNUMBER(SEARCH("KFCH",البيانات!$AM$2:$AM$500)))>0,ROW(البيانات!$AI$2:$AI$500)-ROW(البيانات!$AI$2)+1),16)),"")} | K22: =IF(OR(I22="",J22=""),"",IF(NETWORKDAYS.INTL(I22,J22,"0000011")-1<=2,"✅ ملتزم","❌ غير ملتزم")) | L22: {=IFERROR(INDEX(البيانات!$AJ$2:$AJ$500,SMALL(IF((ISNUMBER(SEARCH("فهد",البيانات!$AM$2:$AM$500))+ISNUMBER(SEARCH("KFCH",البيانات!$AM$2:$AM$500)))>0,ROW(البيانات!$AJ$2:$AJ$500)-ROW(البيانات!$AJ$2)+1),16)),"")}
A23: 17 | B23: {=IFERROR(INDEX(البيانات!$V$2:$V$500,SMALL(IF((ISNUMBER(SEARCH("فهد",البيانات!$AM$2:$AM$500))+ISNUMBER(SEARCH("KFCH",البيانات!$AM$2:$AM$500)))>0,ROW(البيانات!$V$2:$V$500)-ROW(البيانات!$V$2)+1),17)),"")} | C23: {=IFERROR(INDEX(البيانات!$U$2:$U$500,SMALL(IF((ISNUMBER(SEARCH("فهد",البيانات!$AM$2:$AM$500))+ISNUMBER(SEARCH("KFCH",البيانات!$AM$2:$AM$500)))>0,ROW(البيانات!$U$2:$U$500)-ROW(البيانات!$U$2)+1),17)),"")} | D23: {=IFERROR(INDEX(البيانات!$T$2:$T$500,SMALL(IF((ISNUMBER(SEARCH("فهد",البيانات!$AM$2:$AM$500))+ISNUMBER(SEARCH("KFCH",البيانات!$AM$2:$AM$500)))>0,ROW(البيانات!$T$2:$T$500)-ROW(البيانات!$T$2)+1),17)),"")} | E23: {=IFERROR(INDEX(البيانات!$F$2:$F$500,SMALL(IF((ISNUMBER(SEARCH("فهد",البيانات!$AM$2:$AM$500))+ISNUMBER(SEARCH("KFCH",البيانات!$AM$2:$AM$500)))>0,ROW(البيانات!$F$2:$F$500)-ROW(البيانات!$F$2)+1),17)),"")} | F23: {=IFERROR(INDEX(البيانات!$Y$2:$Y$500,SMALL(IF((ISNUMBER(SEARCH("فهد",البيانات!$AM$2:$AM$500))+ISNUMBER(SEARCH("KFCH",البيانات!$AM$2:$AM$500)))>0,ROW(البيانات!$Y$2:$Y$500)-ROW(البيانات!$Y$2)+1),17)),"")} | I23: {=IFERROR(INDEX(البيانات!$P$2:$P$500,SMALL(IF((ISNUMBER(SEARCH("فهد",البيانات!$AM$2:$AM$500))+ISNUMBER(SEARCH("KFCH",البيانات!$AM$2:$AM$500)))>0,ROW(البيانات!$P$2:$P$500)-ROW(البيانات!$P$2)+1),17)),"")} | J23: {=IFERROR(INDEX(البيانات!$AI$2:$AI$500,SMALL(IF((ISNUMBER(SEARCH("فهد",البيانات!$AM$2:$AM$500))+ISNUMBER(SEARCH("KFCH",البيانات!$AM$2:$AM$500)))>0,ROW(البيانات!$AI$2:$AI$500)-ROW(البيانات!$AI$2)+1),17)),"")} | K23: =IF(OR(I23="",J23=""),"",IF(NETWORKDAYS.INTL(I23,J23,"0000011")-1<=2,"✅ ملتزم","❌ غير ملتزم")) | L23: {=IFERROR(INDEX(البيانات!$AJ$2:$AJ$500,SMALL(IF((ISNUMBER(SEARCH("فهد",البيانات!$AM$2:$AM$500))+ISNUMBER(SEARCH("KFCH",البيانات!$AM$2:$AM$500)))>0,ROW(البيانات!$AJ$2:$AJ$500)-ROW(البيانات!$AJ$2)+1),17)),"")}
A24: 18 | B24: {=IFERROR(INDEX(البيانات!$V$2:$V$500,SMALL(IF((ISNUMBER(SEARCH("فهد",البيانات!$AM$2:$AM$500))+ISNUMBER(SEARCH("KFCH",البيانات!$AM$2:$AM$500)))>0,ROW(البيانات!$V$2:$V$500)-ROW(البيانات!$V$2)+1),18)),"")} | C24: {=IFERROR(INDEX(البيانات!$U$2:$U$500,SMALL(IF((ISNUMBER(SEARCH("فهد",البيانات!$AM$2:$AM$500))+ISNUMBER(SEARCH("KFCH",البيانات!$AM$2:$AM$500)))>0,ROW(البيانات!$U$2:$U$500)-ROW(البيانات!$U$2)+1),18)),"")} | D24: {=IFERROR(INDEX(البيانات!$T$2:$T$500,SMALL(IF((ISNUMBER(SEARCH("فهد",البيانات!$AM$2:$AM$500))+ISNUMBER(SEARCH("KFCH",البيانات!$AM$2:$AM$500)))>0,ROW(البيانات!$T$2:$T$500)-ROW(البيانات!$T$2)+1),18)),"")} | E24: {=IFERROR(INDEX(البيانات!$F$2:$F$500,SMALL(IF((ISNUMBER(SEARCH("فهد",البيانات!$AM$2:$AM$500))+ISNUMBER(SEARCH("KFCH",البيانات!$AM$2:$AM$500)))>0,ROW(البيانات!$F$2:$F$500)-ROW(البيانات!$F$2)+1),18)),"")} | F24: {=IFERROR(INDEX(البيانات!$Y$2:$Y$500,SMALL(IF((ISNUMBER(SEARCH("فهد",البيانات!$AM$2:$AM$500))+ISNUMBER(SEARCH("KFCH",البيانات!$AM$2:$AM$500)))>0,ROW(البيانات!$Y$2:$Y$500)-ROW(البيانات!$Y$2)+1),18)),"")} | I24: {=IFERROR(INDEX(البيانات!$P$2:$P$500,SMALL(IF((ISNUMBER(SEARCH("فهد",البيانات!$AM$2:$AM$500))+ISNUMBER(SEARCH("KFCH",البيانات!$AM$2:$AM$500)))>0,ROW(البيانات!$P$2:$P$500)-ROW(البيانات!$P$2)+1),18)),"")} | J24: {=IFERROR(INDEX(البيانات!$AI$2:$AI$500,SMALL(IF((ISNUMBER(SEARCH("فهد",البيانات!$AM$2:$AM$500))+ISNUMBER(SEARCH("KFCH",البيانات!$AM$2:$AM$500)))>0,ROW(البيانات!$AI$2:$AI$500)-ROW(البيانات!$AI$2)+1),18)),"")} | K24: =IF(OR(I24="",J24=""),"",IF(NETWORKDAYS.INTL(I24,J24,"0000011")-1<=2,"✅ ملتزم","❌ غير ملتزم")) | L24: {=IFERROR(INDEX(البيانات!$AJ$2:$AJ$500,SMALL(IF((ISNUMBER(SEARCH("فهد",البيانات!$AM$2:$AM$500))+ISNUMBER(SEARCH("KFCH",البيانات!$AM$2:$AM$500)))>0,ROW(البيانات!$AJ$2:$AJ$500)-ROW(البيانات!$AJ$2)+1),18)),"")}
A25: 19 | B25: {=IFERROR(INDEX(البيانات!$V$2:$V$500,SMALL(IF((ISNUMBER(SEARCH("فهد",البيانات!$AM$2:$AM$500))+ISNUMBER(SEARCH("KFCH",البيانات!$AM$2:$AM$500)))>0,ROW(البيانات!$V$2:$V$500)-ROW(البيانات!$V$2)+1),19)),"")} | C25: {=IFERROR(INDEX(البيانات!$U$2:$U$500,SMALL(IF((ISNUMBER(SEARCH("فهد",البيانات!$AM$2:$AM$500))+ISNUMBER(SEARCH("KFCH",البيانات!$AM$2:$AM$500)))>0,ROW(البيانات!$U$2:$U$500)-ROW(البيانات!$U$2)+1),19)),"")} | D25: {=IFERROR(INDEX(البيانات!$T$2:$T$500,SMALL(IF((ISNUMBER(SEARCH("فهد",البيانات!$AM$2:$AM$500))+ISNUMBER(SEARCH("KFCH",البيانات!$AM$2:$AM$500)))>0,ROW(البيانات!$T$2:$T$500)-ROW(البيانات!$T$2)+1),19)),"")} | E25: {=IFERROR(INDEX(البيانات!$F$2:$F$500,SMALL(IF((ISNUMBER(SEARCH("فهد",البيانات!$AM$2:$AM$500))+ISNUMBER(SEARCH("KFCH",البيانات!$AM$2:$AM$500)))>0,ROW(البيانات!$F$2:$F$500)-ROW(البيانات!$F$2)+1),19)),"")} | F25: {=IFERROR(INDEX(البيانات!$Y$2:$Y$500,SMALL(IF((ISNUMBER(SEARCH("فهد",البيانات!$AM$2:$AM$500))+ISNUMBER(SEARCH("KFCH",البيانات!$AM$2:$AM$500)))>0,ROW(البيانات!$Y$2:$Y$500)-ROW(البيانات!$Y$2)+1),19)),"")} | I25: {=IFERROR(INDEX(البيانات!$P$2:$P$500,SMALL(IF((ISNUMBER(SEARCH("فهد",البيانات!$AM$2:$AM$500))+ISNUMBER(SEARCH("KFCH",البيانات!$AM$2:$AM$500)))>0,ROW(البيانات!$P$2:$P$500)-ROW(البيانات!$P$2)+1),19)),"")} | J25: {=IFERROR(INDEX(البيانات!$AI$2:$AI$500,SMALL(IF((ISNUMBER(SEARCH("فهد",البيانات!$AM$2:$AM$500))+ISNUMBER(SEARCH("KFCH",البيانات!$AM$2:$AM$500)))>0,ROW(البيانات!$AI$2:$AI$500)-ROW(البيانات!$AI$2)+1),19)),"")} | K25: =IF(OR(I25="",J25=""),"",IF(NETWORKDAYS.INTL(I25,J25,"0000011")-1<=2,"✅ ملتزم","❌ غير ملتزم")) | L25: {=IFERROR(INDEX(البيانات!$AJ$2:$AJ$500,SMALL(IF((ISNUMBER(SEARCH("فهد",البيانات!$AM$2:$AM$500))+ISNUMBER(SEARCH("KFCH",البيانات!$AM$2:$AM$500)))>0,ROW(البيانات!$AJ$2:$AJ$500)-ROW(البيانات!$AJ$2)+1),19)),"")}
A26: 20 | B26: {=IFERROR(INDEX(البيانات!$V$2:$V$500,SMALL(IF((ISNUMBER(SEARCH("فهد",البيانات!$AM$2:$AM$500))+ISNUMBER(SEARCH("KFCH",البيانات!$AM$2:$AM$500)))>0,ROW(البيانات!$V$2:$V$500)-ROW(البيانات!$V$2)+1),20)),"")} | C26: {=IFERROR(INDEX(البيانات!$U$2:$U$500,SMALL(IF((ISNUMBER(SEARCH("فهد",البيانات!$AM$2:$AM$500))+ISNUMBER(SEARCH("KFCH",البيانات!$AM$2:$AM$500)))>0,ROW(البيانات!$U$2:$U$500)-ROW(البيانات!$U$2)+1),20)),"")} | D26: {=IFERROR(INDEX(البيانات!$T$2:$T$500,SMALL(IF((ISNUMBER(SEARCH("فهد",البيانات!$AM$2:$AM$500))+ISNUMBER(SEARCH("KFCH",البيانات!$AM$2:$AM$500)))>0,ROW(البيانات!$T$2:$T$500)-ROW(البيانات!$T$2)+1),20)),"")} | E26: {=IFERROR(INDEX(البيانات!$F$2:$F$500,SMALL(IF((ISNUMBER(SEARCH("فهد",البيانات!$AM$2:$AM$500))+ISNUMBER(SEARCH("KFCH",البيانات!$AM$2:$AM$500)))>0,ROW(البيانات!$F$2:$F$500)-ROW(البيانات!$F$2)+1),20)),"")} | F26: {=IFERROR(INDEX(البيانات!$Y$2:$Y$500,SMALL(IF((ISNUMBER(SEARCH("فهد",البيانات!$AM$2:$AM$500))+ISNUMBER(SEARCH("KFCH",البيانات!$AM$2:$AM$500)))>0,ROW(البيانات!$Y$2:$Y$500)-ROW(البيانات!$Y$2)+1),20)),"")} | I26: {=IFERROR(INDEX(البيانات!$P$2:$P$500,SMALL(IF((ISNUMBER(SEARCH("فهد",البيانات!$AM$2:$AM$500))+ISNUMBER(SEARCH("KFCH",البيانات!$AM$2:$AM$500)))>0,ROW(البيانات!$P$2:$P$500)-ROW(البيانات!$P$2)+1),20)),"")} | J26: {=IFERROR(INDEX(البيانات!$AI$2:$AI$500,SMALL(IF((ISNUMBER(SEARCH("فهد",البيانات!$AM$2:$AM$500))+ISNUMBER(SEARCH("KFCH",البيانات!$AM$2:$AM$500)))>0,ROW(البيانات!$AI$2:$AI$500)-ROW(البيانات!$AI$2)+1),20)),"")} | K26: =IF(OR(I26="",J26=""),"",IF(NETWORKDAYS.INTL(I26,J26,"0000011")-1<=2,"✅ ملتزم","❌ غير ملتزم")) | L26: {=IFERROR(INDEX(البيانات!$AJ$2:$AJ$500,SMALL(IF((ISNUMBER(SEARCH("فهد",البيانات!$AM$2:$AM$500))+ISNUMBER(SEARCH("KFCH",البيانات!$AM$2:$AM$500)))>0,ROW(البيانات!$AJ$2:$AJ$500)-ROW(البيانات!$AJ$2)+1),20)),"")}
A28: 📊 الإحصائيات
A29: إجمالي الإحالات: | B29: {=SUMPRODUCT((ISNUMBER(SEARCH("فهد",البيانات!$AM$2:$AM$500))+ISNUMBER(SEARCH("KFCH",البيانات!$AM$2:$AM$500)))>0)*1} -> 0
A30: ✅ ملتزم: | B30: =COUNTIF(K7:K26,"✅ ملتزم") -> 1
A31: ❌ غير ملتزم: | B31: =COUNTIF(K7:K26,"❌ غير ملتزم") -> 0

Sheet إحالات_صبيا
A1: 🏥 مستشفى صبيا العام - قائمة الإحالات
A2: عدد الحالات المحالة: | B2: =COUNTIF(البيانات!$AS:$AS,"*صبيا*") -> 38
A3: # | B3: السجل المدني | C3: اسم المريضة | D3: العمر | E3: القطاع | F3: رقم الجوال | G3: مستوى الخطر | H3: توصية الإحالة | I3: تاريخ الزيارة | J3: تاريخ الموعد | K3: الالتزام | L3: افادة الحضور | M3: تصنيف المنسق | N3: ملاحظات المنسق
A4: {=IFERROR(SMALL(IF(البيانات!$AS$2:$AS$265="مستشفى صبيا العام",البيانات!$AT$2:$AT$265),1),"")} -> 5 | B4: {=IF(A4="","",INDEX(البيانات!$V$2:$V$265,A4))} -> 1096356959 | C4: {=IF(A4="","",INDEX(البيانات!$U$2:$U$265,A4))} -> علا الله حسن محمد الليل | D4: {=IF(A4="","",INDEX(البيانات!$T$2:$T$265,A4))} -> 46 | E4: {=IF(A4="","",INDEX(البيانات!$F$2:$F$265,A4))} -> القطاع الغربي | F4: {=IF(A4="","",INDEX(البيانات!$Y$2:$Y$265,A4))} -> 0556826709 | I4: {=IF(A4="","",INDEX(البيانات!$P$2:$P$265,A4))} -> 46079 | J4: {=IF(A4="","",INDEX(البيانات!$AI$2:$AI$265,A4))} -> 5/3/2026 | K4: =IF(OR(A4="",J4="",I4=""),"",IF(NETWORKDAYS.INTL(I4,J4,"0000011")-1<=2,"✅ ملتزم","❌ غير ملتزم")) -> ❌ غير ملتزم | L4: {=IF(A4="","",INDEX(البيانات!$AJ$2:$AJ$265,A4))} -> تم الحظور
A5: {=IFERROR(SMALL(IF(البيانات!$AS$2:$AS$265="مستشفى صبيا العام",البيانات!$AT$2:$AT$265),2),"")} -> 15 | B5: {=IF(A5="","",INDEX(البيانات!$V$2:$V$265,A5))} -> 1120110281 | C5: {=IF(A5="","",INDEX(البيانات!$U$2:$U$265,A5))} -> SAHAR AHMED BIN MOHAMMED HAKAMI | D5: {=IF(A5="","",INDEX(البيانات!$T$2:$T$265,A5))} -> 24 | E5: {=IF(A5="","",INDEX(البيانات!$F$2:$F$265,A5))} -> القطاع الغربي | F5: {=IF(A5="","",INDEX(البيانات!$Y$2:$Y$265,A5))} -> 0508985743 | I5: {=IF(A5="","",INDEX(البيانات!$P$2:$P$265,A5))} -> 46089 | J5: {=IF(A5="","",INDEX(البيانات!$AI$2:$AI$265,A5))} -> 12/3/2026 | K5: =IF(OR(A5="",J5="",I5=""),"",IF(NETWORKDAYS.INTL(I5,J5,"0000011")-1<=2,"✅ ملتزم","❌ غير ملتزم")) -> ❌ غير ملتزم | L5: {=IF(A5="","",INDEX(البيانات!$AJ$2:$AJ$265,A5))} -> تم الحظور
A6: {=IFERROR(SMALL(IF(البيانات!$AS$2:$AS$265="مستشفى صبيا العام",البيانات!$AT$2:$AT$265),3),"")} -> 16 | B6: {=IF(A6="","",INDEX(البيانات!$V$2:$V$265,A6))} -> 1115266551 | C6: {=IF(A6="","",INDEX(البيانات!$U$2:$U$265,A6))} -> Rayhanah Hassan Yahya | D6: {=IF(A6="","",INDEX(البيانات!$T$2:$T$265,A6))} -> 24 | E6: {=IF(A6="","",INDEX(البيانات!$F$2:$F$265,A6))} -> القطاع الغربي | F6: {=IF(A6="","",INDEX(البيانات!$Y$2:$Y$265,A6))} -> 554195384 | I6: {=IF(A6="","",INDEX(البيانات!$P$2:$P$265,A6))} -> 46089 | J6: 46103 | K6: =IF(OR(A6="",J6="",I6=""),"",IF(NETWORKDAYS.INTL(I6,J6,"0000011")-1<=2,"✅ ملتزم","❌ غير ملتزم")) -> ❌ غير ملتزم | L6: {=IF(A6="","",INDEX(البيانات!$AJ$2:$AJ$265,A6))} -> تم الحظور
A7: {=IFERROR(SMALL(IF(البيانات!$AS$2:$AS$265="مستشفى صبيا العام",البيانات!$AT$2:$AT$265),4),"")} -> 17 | B7: {=IF(A7="","",INDEX(البيانات!$V$2:$V$265,A7))} -> 1061102602 | C7: {=IF(A7="","",INDEX(البيانات!$U$2:$U$265,A7))} -> امنة سلمان مفرح غزواني | D7: {=IF(A7="","",INDEX(البيانات!$T$2:$T$265,A7))} -> 37 | E7: {=IF(A7="","",INDEX(البيانات!$F$2:$F$265,A7))} -> القطاع الجبلي | F7: {=IF(A7="","",INDEX(البيانات!$Y$2:$Y$265,A7))} -> 0594808888 | I7: {=IF(A7="","",INDEX(البيانات!$P$2:$P$265,A7))} -> 46089 | J7: {=IF(A7="","",INDEX(البيانات!$AI$2:$AI$265,A7))} -> 12/3/2026 | K7: =IF(OR(A7="",J7="",I7=""),"",IF(NETWORKDAYS.INTL(I7,J7,"0000011")-1<=2,"✅ ملتزم","❌ غير ملتزم")) -> ❌ غير ملتزم | L7: {=IF(A7="","",INDEX(البيانات!$AJ$2:$AJ$265,A7))} -> لم تحظر
A8: {=IFERROR(SMALL(IF(البيانات!$AS$2:$AS$265="مستشفى صبيا العام",البيانات!$AT$2:$AT$265),5),"")} -> 18 | B8: {=IF(A8="","",INDEX(البيانات!$V$2:$V$265,A8))} -> 1055011710 | C8: {=IF(A8="","",INDEX(البيانات!$U$2:$U$265,A8))} -> سعاد سلمان بكري | D8: {=IF(A8="","",INDEX(البيانات!$T$2:$T$265,A8))} -> 40 | E8: {=IF(A8="","",INDEX(البيانات!$F$2:$F$265,A8))} -> القطاع الغربي | F8: {=IF(A8="","",INDEX(البيانات!$Y$2:$Y$265,A8))} -> 0553346156 | I8: {=IF(A8="","",INDEX(البيانات!$P$2:$P$265,A8))} -> 46089 | J8: {=IF(A8="","",INDEX(البيانات!$AI$2:$AI$265,A8))} -> 12/3/2026 | K8: =IF(OR(A8="",J8="",I8=""),"",IF(NETWORKDAYS.INTL(I8,J8,"0000011")-1<=2,"✅ ملتزم","❌ غير ملتزم")) -> ❌ غير ملتزم | L8: {=IF(A8="","",INDEX(البيانات!$AJ$2:$AJ$265,A8))} -> تم الحظور
A9: {=IFERROR(SMALL(IF(البيانات!$AS$2:$AS$265="مستشفى صبيا العام",البيانات!$AT$2:$AT$265),6),"")} -> 28 | B9: {=IF(A9="","",INDEX(البيانات!$V$2:$V$265,A9))} -> 1117369478 | C9: {=IF(A9="","",INDEX(البيانات!$U$2:$U$265,A9))} -> YARA AMRO ALI ABUHOZAH | D9: {=IF(A9="","",INDEX(البيانات!$T$2:$T$265,A9))} -> 0 | E9: {=IF(A9="","",INDEX(البيانات!$F$2:$F$265,A9))} -> القطاع الغربي | F9: {=IF(A9="","",INDEX(البيانات!$Y$2:$Y$265,A9))} -> 568883343 | I9: {=IF(A9="","",INDEX(البيانات!$P$2:$P$265,A9))} -> 46091 | J9: {=IF(A9="","",INDEX(البيانات!$AI$2:$AI$265,A9))} -> 19/3/2026 | K9: =IF(OR(A9="",J9="",I9=""),"",IF(NETWORKDAYS.INTL(I9,J9,"0000011")-1<=2,"✅ ملتزم","❌ غير ملتزم")) -> ❌ غير ملتزم | L9: {=IF(A9="","",INDEX(البيانات!$AJ$2:$AJ$265,A9))} -> تم الحظور
A10: {=IFERROR(SMALL(IF(البيانات!$AS$2:$AS$265="مستشفى صبيا العام",البيانات!$AT$2:$AT$265),7),"")} -> 33 | B10: {=IF(A10="","",INDEX(البيانات!$V$2:$V$265,A10))} -> 1067750933 | C10: {=IF(A10="","",INDEX(البيانات!$U$2:$U$265,A10))} -> NADA DAWOOD GADI | D10: {=IF(A10="","",INDEX(البيانات!$T$2:$T$265,A10))} -> 0 | E10: {=IF(A10="","",INDEX(البيانات!$F$2:$F$265,A10))} -> القطاع الغربي | F10: {=IF(A10="","",INDEX(البيانات!$Y$2:$Y$265,A10))} -> 0541366345 | I10: {=IF(A10="","",INDEX(البيانات!$P$2:$P$265,A10))} -> 46091 | J10: {=IF(A10="","",INDEX(البيانات!$AI$2:$AI$265,A10))} -> 12/3/2026 | K10: =IF(OR(A10="",J10="",I10=""),"",IF(NETWORKDAYS.INTL(I10,J10,"0000011")-1<=2,"✅ ملتزم","❌ غير ملتزم")) -> ✅ ملتزم | L10: {=IF(A10="","",INDEX(البيانات!$AJ$2:$AJ$265,A10))} -> لم تحظر
A11: {=IFERROR(SMALL(IF(البيانات!$AS$2:$AS$265="مستشفى صبيا العام",البيانات!$AT$2:$AT$265),8),"")} -> 35 | B11: {=IF(A11="","",INDEX(البيانات!$V$2:$V$265,A11))} -> 1083139400 | C11: {=IF(A11="","",INDEX(البيانات!$U$2:$U$265,A11))} -> RAYHANAH SULAIMAN YAHYA SUHLULI | D11: {=IF(A11="","",INDEX(البيانات!$T$2:$T$265,A11))} -> 0 | E11: {=IF(A11="","",INDEX(البيانات!$F$2:$F$265,A11))} -> القطاع الغربي | F11: {=IF(A11="","",INDEX(البيانات!$Y$2:$Y$265,A11))} -> 0530772945 | I11: {=IF(A11="","",INDEX(البيانات!$P$2:$P$265,A11))} -> 46091 | J11: 46103 | K11: =IF(OR(A11="",J11="",I11=""),"",IF(NETWORKDAYS.INTL(I11,J11,"0000011")-1<=2,"✅ ملتزم","❌ غير ملتزم")) -> ❌ غير ملتزم | L11: {=IF(A11="","",INDEX(البيانات!$AJ$2:$AJ$265,A11))} -> تم الحظور
